Workbook

Sheet DATA_UBER
A1: Nom chauffeur Uber | B1: Prénom | C1: UUID Chauffeur | D1: Courses (D) | E1: Frais service Uber | F1: Péages (F) | G1: Pourboires (G) | H1: Remboursements | I1: Frais annulation | J1: Espèces collectées (J) | K1: Promotions / Bonus (K) | L1: Frais réservation Uber (L) | M1: Ajustements courses | N1: Déductions diverses | O1: Recharges | P1: Équipements | Q1: Régularisations diverses | R1: Régularisations / Péages (R) | S1: Retenues fiscales | T1: Acomptes | U1: Autres déductions | V1: Montant brut | W1: Montant net | X1: Banque | Y1: Date versement | Z1: Virement Réel Uber (Z)
A2: SIRE CYRIL NIAKATE | B2: SIRE CYRIL | C2: 983c63ed-2f31-43bd-b79f-b677ca5065fa | D2: 51.73 | E2: 0 | F2: 0 | G2: 0.89 | H2: 0 | I2: 0 | J2: 0 | K2: 1.19 | L2: 0.04 | M2: 0 | N2: 0 | O2: 0 | P2: 0 | Q2: 0 | R2: 0 | S2: 0 | T2: 0 | U2: 0 | V2: 53.81 | W2: 53.77 | X2: QONTO | Y2: 2026-09-28 | Z2: =IF(A2="", "", (D2+G2+K2+R2) - ABS(J2) - ABS(L2)) -> 53.77
A3: Ramzi Khannoussi | B3: Ramzi | C3: 7e6b9ac8-24f0-4325-902e-2631b16f1f54 | D3: 34.07 | E3: 0 | F3: 0 | G3: 0 | H3: 0 | I3: 0 | J3: 12.95 | K3: 0 | L3: 0 | M3: 0 | N3: 0 | O3: 0 | P3: 0 | Q3: 0 | R3: 0 | S3: 0 | T3: 0 | U3: 0 | V3: 34.07 | W3: 21.12 | X3: QONTO | Y3: 2026-09-28 | Z3: =IF(A3="", "", (D3+G3+K3+R3) - ABS(J3) - ABS(L3)) -> 21.12
A4: Ratiba Beldjoudi | B4: Ratiba | C4: e4157312-32c8-469d-b099-30f3b16cbe69 | D4: 9 | E4: 0 | F4: 0 | G4: 0 | H4: 0 | I4: 0 | J4: 0 | K4: 0.28 | L4: 0 | M4: 0 | N4: 0 | O4: 0 | P4: 0 | Q4: 0 | R4: 0 | S4: 0 | T4: 0 | U4: 0 | V4: 9.28 | W4: 9.28 | X4: QONTO | Y4: 2026-09-28 | Z4: =IF(A4="", "", (D4+G4+K4+R4) - ABS(J4) - ABS(L4)) -> 9.28
A5: Christopher Andrew Mongis | B5: Christopher Andrew | C5: 2d271984-777e-4942-8f22-6c20d8d00036 | D5: 220.64 | E5: 0 | F5: 0 | G5: 2 | H5: 0 | I5: 0 | J5: 43.98 | K5: 1.45 | L5: 0.12 | M5: 0 | N5: 0 | O5: 0 | P5: 0 | Q5: 0 | R5: 0 | S5: 0 | T5: 0 | U5: 0 | V5: 224.09 | W5: 179.99 | X5: QONTO | Y5: 2026-09-28 | Z5: =IF(A5="", "", (D5+G5+K5+R5) - ABS(J5) - ABS(L5)) -> 179.99
A6: ZIAED HAMILA | B6: ZIAED | C6: c301c784-1c1d-44fd-8106-615e30556e7e | D6: 54 | E6: 0 | F6: 0 | G6: 5 | H6: 0 | I6: 0 | J6: 0 | K6: 0 | L6: 0 | M6: 0 | N6: 0 | O6: 0 | P6: 0 | Q6: 0 | R6: 0 | S6: 0 | T6: 0 | U6: 0 | V6: 59 | W6: 59 | X6: QONTO | Y6: 2026-09-28 | Z6: =IF(A6="", "", (D6+G6+K6+R6) - ABS(J6) - ABS(L6)) -> 59
A7: MEHMET ERGUN | B7: MEHMET | C7: 7ed4458a-eaaa-4e6d-98f6-24871c279a8a | D7: 44.25 | E7: 0 | F7: 0 | G7: 0 | H7: 0 | I7: 0 | J7: 0 | K7: 0.18 | L7: 0 | M7: 0 | N7: 0 | O7: 0 | P7: 0 | Q7: 0 | R7: 0 | S7: 0 | T7: 0 | U7: 0 | V7: 44.43 | W7: 44.43 | X7: QONTO | Y7: 2026-09-28 | Z7: =IF(A7="", "", (D7+G7+K7+R7) - ABS(J7) - ABS(L7)) -> 44.43
A8: Abdelaziz Guerfi | B8: Abdelaziz | C8: a53484f4-ce4a-4cbb-9b3a-8652f25c1afa | D8: 216.08 | E8: 0 | F8: 0 | G8: 5 | H8: 0 | I8: 0 | J8: 50.95 | K8: 0 | L8: 0.04 | M8: 0 | N8: 0 | O8: 0 | P8: 0 | Q8: 0 | R8: 0 | S8: 0 | T8: 0 | U8: 0 | V8: 221.08 | W8: 170.09 | X8: QONTO | Y8: 2026-09-28 | Z8: =IF(A8="", "", (D8+G8+K8+R8) - ABS(J8) - ABS(L8)) -> 170.09
A9: FAICAL JABRI | B9: FAICAL | C9: fa89767a-12bb-4a95-b1db-5fb71719a940 | D9: 183.79 | E9: 0 | F9: 0 | G9: 2 | H9: 0 | I9: 0 | J9: 29.9 | K9: 1.6 | L9: 0.12 | M9: 0 | N9: 0 | O9: 0 | P9: 0 | Q9: 0 | R9: 0 | S9: 0 | T9: 0 | U9: 0 | V9: 187.39 | W9: 157.37 | X9: QONTO | Y9: 2026-09-28 | Z9: =IF(A9="", "", (D9+G9+K9+R9) - ABS(J9) - ABS(L9)) -> 157.37
A10: Karim Sidibe | B10: Karim | C10: 66310da7-a454-4902-ba89-dc1ea3fa89af | D10: 19.86 | E10: 0 | F10: 0 | G10: 0 | H10: 0 | I10: 0 | J10: 0 | K10: 0.15 | L10: 0.04 | M10: 0 | N10: 0 | O10: 0 | P10: 0 | Q10: 0 | R10: 0 | S10: 0 | T10: 0 | U10: 0 | V10: 20.01 | W10: 19.97 | X10: QONTO | Y10: 2026-09-28 | Z10: =IF(A10="", "", (D10+G10+K10+R10) - ABS(J10) - ABS(L10)) -> 19.97
A11: JOVAN MILIC | B11: JOVAN | C11: ae172f19-9351-4176-9405-f691a5389f01 | D11: 66.59 | E11: 0 | F11: 0 | G11: 0 | H11: 0 | I11: 0 | J11: 12.8 | K11: 0.41 | L11: 0.04 | M11: 0 | N11: 0 | O11: 0 | P11: 0 | Q11: 0 | R11: 0 | S11: 0 | T11: 0 | U11: 0 | V11: 67 | W11: 54.16 | X11: QONTO | Y11: 2026-09-28 | Z11: =IF(A11="", "", (D11+G11+K11+R11) - ABS(J11) - ABS(L11)) -> 54.16
A12: Bechir Ben Smida | B12: Bechir | C12: a0e498bc-3c9b-4c82-bc49-18718ccca9f0 | D12: 161 | E12: 0 | F12: 0 | G12: 0 | H12: 0 | I12: 0 | J12: 0 | K12: 1.1 | L12: 0.08 | M12: 0 | N12: 0 | O12: 0 | P12: 0 | Q12: 0 | R12: 0 | S12: 0 | T12: 0 | U12: 0 | V12: 162.1 | W12: 162.02 | X12: QONTO | Y12: 2026-09-28 | Z12: =IF(A12="", "", (D12+G12+K12+R12) - ABS(J12) - ABS(L12)) -> 162.02
A13: Robert-Ionut Neagu | B13: Robert-Ionut | C13: ba779469-ba34-4105-ae7e-5da93a3217f9 | D13: 19.31 | E13: 0 | F13: 0 | G13: 0 | H13: 0 | I13: 0 | J13: 0 | K13: 0.66 | L13: 0 | M13: 0 | N13: 0 | O13: 0 | P13: 0 | Q13: 0 | R13: 0 | S13: 0 | T13: 0 | U13: 0 | V13: 19.97 | W13: 19.97 | X13: QONTO | Y13: 2026-09-28 | Z13: =IF(A13="", "", (D13+G13+K13+R13) - ABS(J13) - ABS(L13)) -> 19.97
... A27: FATHIA BOUFALGHA | B27: FATHIA | C27: 66cfb448-2a87-41ba-97f2-f0bb51b9b165 | D27: 154.59 | E27: 0 | F27: 0 | G27: 5 | H27: 0 | I27: 0 | J27: 0 | K27: 0.3 | L27: 0 | M27: 0 | N27: 0 | O27: 0 | P27: 0 | Q27: 0 | R27: 0 | S27: 0 | T27: 0 | U27: 0 | V27: 159.89 | W27: 159.89 | X27: QONTO | Y27: 2026-09-28 | Z27: =IF(A27="", "", (D27+G27+K27+R27) - ABS(J27) - ABS(L27)) -> 159.89

Sheet DATA_BOLT
A1: Nom chauffeur Bolt | B1: Email | C1: Téléphone | D1: ID Bolt | E1: Brut Courses App (E) | F1: Brut Courses Autres (F) | G1: Espèces collectées chauffeur (G) | H1: Bonus campagnes (H) | I1: Compensations (I) | J1: Primes objectifs (J) | K1: Pourboires Bolt (K) | L1: Dédommagements (L) | M1: Péages (M) | N1: Frais annulation (N) | O1: Commission Bolt principale (O) | P1: Commission Bolt secondaire (P) | Q1: Autres frais Bolt (Q) | R1: Régularisation commission (R) | S1: Remboursements clients (S) | T1: Frais attente (T) | U1: Ajustements manuels (U) | V1: Autres crédits 1 (V) | W1: Autres crédits 2 (W) | X1: Statut (X) | Y1: Date relevé (Y) | Z1: Virement Réel Bolt (Z)
A2: Abdoul Azize MOHAMED SAFIR | B2: abazizsafir.pro@gmail.com | C2: +33761529386 | D2: 69ca2620-9994-4a35-ae6d-8b03212f66a2 | E2: 178.2 | F2: 430.2 | G2: 361.9 | H2: 29 | I2: 0 | J2: 0 | K2: 0 | L2: 0 | M2: 0 | N2: 7 | O2: 149.28 | P2: 0 | Q2: 0 | R2: 0 | S2: 0 | T2: 0 | U2: 0 | V2: 0 | W2: 0 | X2: Actif | Y2: 2026-09-28 | Z2: =IF(A2="", "", (E2+F2+H2+I2+J2+K2+L2+N2+V2+W2) - ABS(O2+P2+Q2+S2) - ABS(G2)) -> 133.22
A3: Adam Machtou | B3: machtou.adam@gmail.com | C3: +33618757203 | D3: 497378a6-59fb-4727-b3ab-22a1046a8e4b | E3: 186.2 | F3: 12 | G3: 12 | H3: 0 | I3: 0 | J3: 0 | K3: 0 | L3: 0 | M3: 0 | N3: 0 | O3: 49.08 | P3: 0 | Q3: 0 | R3: 0 | S3: 0 | T3: 0 | U3: 0 | V3: 0 | W3: 0 | X3: Actif | Y3: 2026-09-28 | Z3: =IF(A3="", "", (E3+F3+H3+I3+J3+K3+L3+N3+V3+W3) - ABS(O3+P3+Q3+S3) - ABS(G3)) -> 137.12
A4: Alhassane Balde | B4: alh.balde05@gmail.com | C4: +33783639299 | D4: 3f20ff10-9e34-467e-ab69-3544493ade6d | E4: 0 | F4: 25.7 | G4: 16.7 | H4: 0 | I4: 0 | J4: 0 | K4: 0 | L4: 0 | M4: 0 | N4: 0 | O4: 11.56 | P4: 0 | Q4: 0 | R4: 0 | S4: 0 | T4: 0 | U4: 0 | V4: 0 | W4: 0 | X4: Actif | Y4: 2026-09-28 | Z4: =IF(A4="", "", (E4+F4+H4+I4+J4+K4+L4+N4+V4+W4) - ABS(O4+P4+Q4+S4) - ABS(G4)) -> -2.56
A5: Ali Alouani | B5: ali.alouani.95@gmail.com | C5: +33618122054 | D5: bcf5d87f-9b4c-46a1-95be-66a591f97483 | E5: 590.5 | F5: 308.4 | G5: 246.3 | H5: 2.4 | I5: 0 | J5: 0 | K5: 0 | L5: 0 | M5: 0 | N5: 0 | O5: 246.46 | P5: 0 | Q5: 0 | R5: 0 | S5: 0 | T5: 0 | U5: 0 | V5: 0 | W5: 0 | X5: Actif | Y5: 2026-09-28 | Z5: =IF(A5="", "", (E5+F5+H5+I5+J5+K5+L5+N5+V5+W5) - ABS(O5+P5+Q5+S5) - ABS(G5)) -> 408.54
A6: Ali Kara | B6: ali1978kara@hotmail.fr | C6: +33695644791 | D6: 307fd49a-f4c7-48c8-af8e-2b3005f3adc4 | E6: 355.6 | F6: 0 | G6: 0 | H6: 0 | I6: 0 | J6: 0 | K6: 0 | L6: 0 | M6: 0 | N6: 0 | O6: 87.57 | P6: 0 | Q6: 0 | R6: 0 | S6: 0 | T6: 0 | U6: 0 | V6: 0 | W6: 0 | X6: Actif | Y6: 2026-09-28 | Z6: =IF(A6="", "", (E6+F6+H6+I6+J6+K6+L6+N6+V6+W6) - ABS(O6+P6+Q6+S6) - ABS(G6)) -> 268.03
A7: Aymen Ltifi | B7: ltifiservices@outlook.com | C7: +33760731822 | D7: b19b658d-d123-458b-8254-f36d57c2409d | E7: 15.7 | F7: 0 | G7: 0 | H7: 0 | I7: 0 | J7: 0 | K7: 0 | L7: 0 | M7: 0 | N7: 0 | O7: 4.26 | P7: 0 | Q7: 0 | R7: 0 | S7: 0 | T7: 0 | U7: 0 | V7: 0 | W7: 0 | X7: Actif | Y7: 2026-09-28 | Z7: =IF(A7="", "", (E7+F7+H7+I7+J7+K7+L7+N7+V7+W7) - ABS(O7+P7+Q7+S7) - ABS(G7)) -> 11.44
A8: Bouchaïb Belkharras | B8: bouch.bb@hotmail.com | C8: +33658123002 | D8: 5c67fc93-d40b-4960-be79-cc7963c0937b | E8: 474.4 | F8: 164 | G8: 136.7 | H8: 0 | I8: 0 | J8: 0 | K8: 0 | L8: 0 | M8: 0 | N8: 7 | O8: 158.12 | P8: 0 | Q8: 0 | R8: 0 | S8: 0 | T8: 0 | U8: 0 | V8: 0 | W8: 0 | X8: Actif | Y8: 2026-09-28 | Z8: =IF(A8="", "", (E8+F8+H8+I8+J8+K8+L8+N8+V8+W8) - ABS(O8+P8+Q8+S8) - ABS(G8)) -> 350.58
A9: Brandon Jean Jimmy Louissaint | B9: louissaintbrandon@hotmail.com | C9: +33635481157 | D9: b60e6602-1052-41a1-9fc2-1affbf421ad9 | E9: 460.8 | F9: 409.2 | G9: 334.8 | H9: 0 | I9: 0 | J9: 0 | K9: 8 | L9: 6.35 | M9: 0 | N9: 0 | O9: 219.01 | P9: 0 | Q9: 0 | R9: 0 | S9: 0 | T9: 0 | U9: 0 | V9: 0 | W9: 0 | X9: Actif | Y9: 2026-09-28 | Z9: =IF(A9="", "", (E9+F9+H9+I9+J9+K9+L9+N9+V9+W9) - ABS(O9+P9+Q9+S9) - ABS(G9)) -> 330.54
A10: Elias Bihi | B10: Bihieliaspro@gmail.com | C10: +33749483638 | D10: dd37da70-0511-47bd-8a81-849c6fd8cc04 | E10: 234.5 | F10: 98.6 | G10: 81.6 | H10: 79 | I10: 0 | J10: 0 | K10: 0 | L10: 0 | M10: 0 | N10: 7 | O10: 83.05 | P10: 0 | Q10: 0 | R10: 0 | S10: 0 | T10: 0 | U10: 0 | V10: 0 | W10: 0 | X10: Actif | Y10: 2026-09-28 | Z10: =IF(A10="", "", (E10+F10+H10+I10+J10+K10+L10+N10+V10+W10) - ABS(O10+P10+Q10+S10) - ABS(G10)) -> 254.45
A11: Foued Karoui | B11: karfoued@gmail.com | C11: +33625815497 | D11: 9a7fcf32-1038-4149-84ff-8d5b434d9b6a | E11: 231.5 | F11: 0 | G11: 0 | H11: 0 | I11: 0 | J11: 0 | K11: 0 | L11: 0 | M11: 0 | N11: 7 | O11: 64.37 | P11: 0 | Q11: 0 | R11: 0 | S11: 5 | T11: 0 | U11: 0 | V11: 0 | W11: 0 | X11: Actif | Y11: 2026-09-28 | Z11: =IF(A11="", "", (E11+F11+H11+I11+J11+K11+L11+N11+V11+W11) - ABS(O11+P11+Q11+S11) - ABS(G11)) -> 169.13
A12: Hassene KHIARI | B12: hassenekhiari9@gmail.com | C12: +330616045890 | D12: 65e9fddf-6e9a-4982-a850-745818097338 | E12: 387.3 | F12: 98.1 | G12: 84.5 | H12: 0 | I12: 0 | J12: 0 | K12: 2 | L12: 0.4 | M12: 0 | N12: 7 | O12: 115.71 | P12: 0 | Q12: 0 | R12: 0 | S12: 0 | T12: 0 | U12: 0 | V12: 0 | W12: 0 | X12: Actif | Y12: 2026-09-28 | Z12: =IF(A12="", "", (E12+F12+H12+I12+J12+K12+L12+N12+V12+W12) - ABS(O12+P12+Q12+S12) - ABS(G12)) -> 294.59
A13: Haythem Dhifi | B13: dhifi.haythem.hd@gmail.com | C13: +33612674248 | D13: 4def7bfb-ffe0-4813-9f77-15f89b216145 | E13: 63.5 | F13: 139.9 | G13: 116.3 | H13: 39.64 | I13: 0 | J13: 0 | K13: 0 | L13: 0 | M13: 0 | N13: 0 | O13: 48.89 | P13: 0 | Q13: 0 | R13: 0 | S13: 0 | T13: 0 | U13: 0 | V13: 0 | W13: 0 | X13: Actif | Y13: 2026-09-28 | Z13: =IF(A13="", "", (E13+F13+H13+I13+J13+K13+L13+N13+V13+W13) - ABS(O13+P13+Q13+S13) - ABS(G13)) -> 77.85
... A36: Ziaed Hamila | B36: Teezere@outlook.fr | C36: +33650235792 | D36: 8831f293-8237-4e7e-9123-54811b9034bf | E36: 784.6 | F36: 0 | G36: 0 | H36: 31 | I36: 0 | J36: 0 | K36: 7.2 | L36: 0 | M36: 0 | N36: 14 | O36: 187.68 | P36: 0 | Q36: 0 | R36: 0 | S36: 0 | T36: 0 | U36: 0 | V36: 0 | W36: 0 | X36: Actif | Y36: 2026-09-28 | Z36: =IF(A36="", "", (E36+F36+H36+I36+J36+K36+L36+N36+V36+W36) - ABS(O36+P36+Q36+S36) - ABS(G36)) -> 649.12

Sheet ANNUAIRE_FLOTTE
A1: N° | B1: Nom chauffeur | C1: Nom Uber (CSV) | D1: Nom Bolt (CSV) | E1: E-mail Uber | F1: E-mail Bolt | G1: Téléphone Uber | H1: Téléphone Bolt | I1: IBAN Qonto | J1: Forfait Rattachement (€)
A2: 01 | B2: Abdallah Hamzi | C2: ABDALLAH HAMZI | E2: hamzi.obayda@gmail.com | G2: +33624017099 | J2: 50
A3: 02 | B3: Abdoul Azize Mohamed Safir | C3: ABDOUL AZIZE MOHAMED SAFIR | D3: Abdoul Azize MOHAMED SAFIR | E3: abazizsafir.pro@gmail.com | F3: abazizsafir.pro@gmail.com | G3: +33761529386 | H3: +33761529386 | J3: 50
A4: 03 | B4: Bechir Ben Smida | C4: Bechir Ben Smida | E4: bsbm67@gmail.com | G4: +33762923919 | J4: 50
A5: 04 | B5: Fathia Boufalgha | C5: FATHIA BOUFALGHA | E5: titiprestige75@gmail.com | G5: +33759625661 | J5: 50
A6: 05 | B6: Rachid Chinoune | C6: rachid CHINOUNE | D6: Rachid Chinoune | E6: rachidchinoune@yahoo.fr | F6: crtp2023@gmail.com | G6: +33619305126 | H6: +33619305126 | J6: 50
A7: 06 | B7: Salah Fitouri | C7: Salah Fitouri | E7: Salih071@live.fr | G7: +33627393006 | J7: 50
A8: 07 | B8: Bouchaib Belkharras | C8: Bouchaib Belkharras | D8: Bouchaïb Belkharras | E8: belbouch92@gmail.com | F8: bouch.bb@hotmail.com | G8: +33658123002 | H8: +33658123002 | J8: 60
A9: 08 | B9: Brandon Jean Jimmy Louissaint | C9: BRANDON JEAN-JIMMY LOUISSAINT | D9: Brandon Jean Jimmy Louissaint | E9: louissaintbrandon@hotmail.com | F9: louissaintbrandon@hotmail.com | G9: +33635481157 | H9: +33635481157 | J9: 60
A10: 09 | B10: Farid Adkhis | C10: Farid Adkhis | D10: Farid Adkhis | E10: Farid.adk@gmail.com | F10: Farid.adk@gmail.com | G10: +33651950695 | H10: +33651950695 | J10: 60
A11: 10 | B11: Imane Sarraj | C11: Imane Sarraj | D11: Imane Sarraj | E11: imane.sar2009@gmail.com | F11: imane.sar2009@gmail.com | G11: +33658430022 | H11: +33658430022 | J11: 60
A12: 11 | B12: Mehmet Ergun | C12: MEHMET ERGUN | D12: Mehmet Ergun | E12: mht.egn1@icloud.com | F12: Mht.Egn1@icloud.com | G12: +33782313002 | H12: +33782313002 | J12: 60
A13: 12 | B13: Mohamed Aloui | C13: MOHAMED ALOUi | D13: Mohamed Aloui | E13: fainflash@hotmail.com | F13: Fainflash@hotmail.com | G13: +33762769951 | H13: +33762769951 | J13: 60
A14: 13 | B14: Omar Chemkhi | C14: Omar Chemkhi | E14: omarchemkhioc@gmail.com | G14: +33783433834 | J14: 60
A15: 14 | B15: Raoul Mansfeld Bemma | C15: Raoul Mansfeld Bemma | D15: Raoul Mansfeld Bemma | E15: raoulbemma0@gmail.com | F15: bemra@hotmail.fr | G15: +33672345507 | H15: +33672345507 | J15: 60
A16: 15 | B16: Ratiba Beldjoudi | C16: Ratiba Beldjoudi | D16: Ratiba GUESRI | E16: amir2014bba@hotmail.com | F16: beldjoudilina@hotmail.fr | G16: +33695084256 | H16: +33695084256 | J16: 60
A17: 16 | B17: Zahia Guesri | C17: Zahia Guesri | D17: Zahia Guesri | E17: c_zahwa@hotmail.com | F17: zaza.guess@hotmail.fr | G17: +33669354856 | H17: +33669354856 | J17: 60
A18: 17 | B18: Abdel Mouamane Chelaif | C18: Abdel Mouamane Chelaif | D18: Abdel Mouamane CHELAIF | E18: chelaifmoumen@gmail.com | F18: chelaifmoumen@gmail.com | G18: +33753606026 | H18: +33753606026 | J18: 50
A19: 18 | B19: Abdelaziz Guerfi | C19: Abdelaziz Guerfi | E19: guerfiaziz75@gmail.com | G19: +33671648042 | J19: 50
A20: 19 | B20: Abdullah Kartal | C20: Abdullah Kartal | D20: Abdullah Kartal | E20: abdullahkartal@outlook.fr | F20: abdullahkartal@outlook.fr | G20: +33782374844 | H20: +33782374844 | J20: 50
A21: 20 | B21: Adam Machtou | C21: Adam MACHTOU | D21: Adam Machtou | E21: machtou.adam@gmail.com | F21: machtou.adam@gmail.com | G21: +33618757203 | H21: +33618757203 | J21: 50
A22: 21 | B22: Adel Benabdelouahed | C22: ADEL BENABDELOUAHED | D22: Mohammed Adel benabdelouahed | E22: adelbenan@gmail.com | F22: adelbenan@gmail.com | G22: +33782790937 | H22: +33782790937 | J22: 50
A23: 22 | B23: Ahmed Kherfouche | C23: Ahmed Kherfouche | E23: cena2309@hotmail.fr | G23: +33612943281 | J23: 50
A24: 23 | B24: Alhassane Balde | C24: Alhassane Balde | D24: Alhassane Balde | E24: alh.balde05@gmail.com | F24: alh.balde05@gmail.com | G24: +33783639299 | H24: +33783639299 | J24: 50
A25: 24 | B25: Ali Alouani | C25: Ali Alouani | D25: Ali Alouani | E25: ali.alouani.95@gmail.com | F25: ali.alouani.95@gmail.com | G25: +33618122054 | H25: +33618122054 | J25: 50
A26: 25 | B26: Asma Kissi | C26: ASMA KISSI | E26: kissiasma333@gmail.com | G26: +33626907046 | J26: 50
A27: 26 | B27: Aymen Ltifi | C27: Aymen Ltifi | D27: Aymen Ltifi | E27: ltifiservices@outlook.com | F27: ltifiservices@outlook.com | G27: +33760731822 | H27: +33760731822 | J27: 50
A28: 27 | B28: Bilel Bouhali | C28: Bilel Bouhali | E28: thecompany2275@gmail.com | G28: +33743767400 | J28: 50
A29: 28 | B29: Brahim Aloui | C29: Brahim Aloui | D29: brahim aloui | E29: alouibrahim@ymail.com | F29: alouibrahim@ymail.com | G29: +33624959758 | H29: +33624959758 | J29: 50
A30: 29 | B30: Bryan Grégory Michaud | C30: Bryan Grégory Michaud | D30: Bryan Gregory Michaud | E30: bryan.michaud11@gmail.com | F30: bryan.michaud11@gmail.com | G30: +33783633084 | H30: +33783633084 | J30: 50
A31: 30 | B31: Christopher Andrew Mongis | C31: Christopher Andrew Mongis | E31: mongis.christopher77@gmail.com | G31: +33605838100 | J31: 50
A32: 31 | B32: Daba Gandega | C32: Daba Gandega | E32: dg93240@hotmail.fr | G32: +33652830506 | J32: 50
A33: 32 | B33: Elias Bihi | C33: ELIAS BIHI | D33: Elias Bihi | E33: bihieliaspro@gmail.com | F33: Bihieliaspro@gmail.com | G33: +33749483638 | H33: +33749483638 | J33: 50
A34: 33 | B34: Elias Hocine Abdellou | C34: ELIAS HOCINE ABDELLOU | E34: eabdellou92@gmail.com | G34: +33676966368 | J34: 50
A35: 34 | B35: Faical Jabri | C35: FAICAL JABRI | E35: faicaljabri@yahoo.fr | G35: +33625654846 | J35: 50
A36: 35 | B36: Foued Karoui | C36: FOUED KAROUI | D36: Foued Karoui | E36: karfoued@gmail.com | F36: karfoued@gmail.com | G36: +33625815497 | H36: +33625815497 | J36: 50
A37: 36 | B37: Hassene Khiari | C37: Hassene Khiari | D37: Hassene KHIARI | E37: le-solitaire@live.com | F37: hassenekhiari9@gmail.com | G37: +33616045890 | H37: +33699048832 | J37: 50
A38: 37 | B38: Haythem Dhifi | C38: Haythem Dhifi | D38: Haythem Dhifi | E38: mizyen82@gmail.com | F38: dhifi.haythem.hd@gmail.com | G38: +33612674248 | H38: +33612674248 | J38: 50
A39: 38 | B39: Helton Jose Coelho Da Veiga | C39: Hélton José Coelho Da Veiga | E39: heltondaveiga2014@gmail.com | G39: +33619098335 | J39: 50
A40: 39 | B40: Issa Tandjigora | C40: ISSA TANDJIGORA | D40: Issa Tandjigora | E40: issasenypro@gmail.com | F40: Issasenypro@gmail.com | G40: +33651962203 | H40: +33638776237 | J40: 50
...

Sheet DASHBOARD_SEMAINE
B1: FLEET OS — TABLEAU DE BORD HEBDOMADAIRE (SEMAINE DU 21 AU 27 SEPTEMBRE 2026)
B2: Conciliation Automatique Multi-Plateformes (Uber & Bolt) • 69 Chauffeurs • Rétrocession SEPA Qonto
B4: TOTAL RÉEL ENCAISSÉ (UBER+BOLT) | F4: SUIVI ESPÈCES TOTALES (UBER+BOLT) | J4: REVENUS RATTACHEMENT FLOTTE | N4: TOTAL NET À VIRER (QONTO)
B5: =SUM(M10:M81) -> 9963.33 | F5: =SUM(J10:J81)+SUM(L10:L81) -> 4673.84 | J5: =SUM(N10:N81) -> 2310 | N5: =SUM(R10:R81) -> 7358.33
A8: 👤 IDENTITÉ DU CHAUFFEUR | C8: 🔗 IDENTIFIANTS PLATEFORMES | E8: 📞 CONTACT & COORDONNÉES | I8: ⚫ PRODUCTION UBER (€) | K8: 🟢 PRODUCTION BOLT (€) | M8: 💰 TOTAL ENCAISSÉ (€) | N8: ⚙️ ARBITRAGES FLOTTE (€) | R8: 🏦 CASE VIREMENT NET (€) | S8: 💳 IBAN QONTO
A9: N° | B9: Nom Prénom (Chauffeur) | C9: Nom Uber | D9: Nom Bolt | E9: Mail Uber | F9: Mail Bolt | G9: Tél. Uber | H9: Tél. Bolt | I9: Virement Réel Uber (€) | J9: Espèces Uber (€) | K9: Virement Réel Bolt (€) | L9: Espèces Bolt (€) | M9: Total Réel Encaissé (Uber + Bolt) (€) | N9: Rattachement (€) | O9: Charges (€) | P9: Bonus (€) | Q9: Malus (€) | R9: CASE VIREMENT (NET À ENVOYER) (€) | S9: RIB / IBAN (QONTO)
A10: 01 | B10: Abdallah Hamzi | C10: ABDALLAH HAMZI | E10: hamzi.obayda@gmail.com | G10: +33624017099 | I10: =IF(B10="", "", IF(OR(C10="", C10="—"), 0, IFNA(XLOOKUP(C10, DATA_UBER!A:A, DATA_UBER!Z:Z, 0), 0))) -> 14.08 | J10: =IF(B10="", "", IF(OR(C10="", C10="—"), 0, IFNA(XLOOKUP(C10, DATA_UBER!A:A, DATA_UBER!J:J, 0), 0))) -> 0 | K10: =IF(B10="", "", IF(OR(D10="", D10="—"), 0, IFNA(XLOOKUP(D10, DATA_BOLT!A:A, DATA_BOLT!Z:Z, 0), 0))) -> 0 | L10: =IF(B10="", "", IF(OR(D10="", D10="—"), 0, IFNA(XLOOKUP(D10, DATA_BOLT!A:A, DATA_BOLT!G:G, 0), 0))) -> 0 | M10: =IF(B10="", "", I10 + K10) -> 14.08 | N10: =IF(B10="", "", IF(OR(I10<>0, K10<>0, J10<>0, L10<>0), IFNA(XLOOKUP(B10, ANNUAIRE_FLOTTE!B:B, ANNUAIRE_FLOTTE!J:J, 50), 50), 0)) -> 50 | O10: 0 | P10: 0 | Q10: 0 | R10: =IF(B10="", "", M10 - N10 - O10 - Q10 + P10) -> -35.92
A11: 02 | B11: Abdoul Azize Mohamed Safir | C11: ABDOUL AZIZE MOHAMED SAFIR | D11: Abdoul Azize MOHAMED SAFIR | E11: abazizsafir.pro@gmail.com | F11: abazizsafir.pro@gmail.com | G11: +33761529386 | H11: +33761529386 | I11: =IF(B11="", "", IF(OR(C11="", C11="—"), 0, IFNA(XLOOKUP(C11, DATA_UBER!A:A, DATA_UBER!Z:Z, 0), 0))) -> 93.96 | J11: =IF(B11="", "", IF(OR(C11="", C11="—"), 0, IFNA(XLOOKUP(C11, DATA_UBER!A:A, DATA_UBER!J:J, 0), 0))) -> 0 | K11: =IF(B11="", "", IF(OR(D11="", D11="—"), 0, IFNA(XLOOKUP(D11, DATA_BOLT!A:A, DATA_BOLT!Z:Z, 0), 0))) -> 133.22 | L11: =IF(B11="", "", IF(OR(D11="", D11="—"), 0, IFNA(XLOOKUP(D11, DATA_BOLT!A:A, DATA_BOLT!G:G, 0), 0))) -> 361.9 | M11: =IF(B11="", "", I11 + K11) -> 227.18 | N11: =IF(B11="", "", IF(OR(I11<>0, K11<>0, J11<>0, L11<>0), IFNA(XLOOKUP(B11, ANNUAIRE_FLOTTE!B:B, ANNUAIRE_FLOTTE!J:J, 50), 50), 0)) -> 50 | O11: 0 | P11: 0 | Q11: 0 | R11: =IF(B11="", "", M11 - N11 - O11 - Q11 + P11) -> 177.18
A12: 03 | B12: Bechir Ben Smida | C12: Bechir Ben Smida | E12: bsbm67@gmail.com | G12: +33762923919 | I12: =IF(B12="", "", IF(OR(C12="", C12="—"), 0, IFNA(XLOOKUP(C12, DATA_UBER!A:A, DATA_UBER!Z:Z, 0), 0))) -> 162.02 | J12: =IF(B12="", "", IF(OR(C12="", C12="—"), 0, IFNA(XLOOKUP(C12, DATA_UBER!A:A, DATA_UBER!J:J, 0), 0))) -> 0 | K12: =IF(B12="", "", IF(OR(D12="", D12="—"), 0, IFNA(XLOOKUP(D12, DATA_BOLT!A:A, DATA_BOLT!Z:Z, 0), 0))) -> 0 | L12: =IF(B12="", "", IF(OR(D12="", D12="—"), 0, IFNA(XLOOKUP(D12, DATA_BOLT!A:A, DATA_BOLT!G:G, 0), 0))) -> 0 | M12: =IF(B12="", "", I12 + K12) -> 162.02 | N12: =IF(B12="", "", IF(OR(I12<>0, K12<>0, J12<>0, L12<>0), IFNA(XLOOKUP(B12, ANNUAIRE_FLOTTE!B:B, ANNUAIRE_FLOTTE!J:J, 50), 50), 0)) -> 50 | O12: 0 | P12: 0 | Q12: 0 | R12: =IF(B12="", "", M12 - N12 - O12 - Q12 + P12) -> 112.02
A13: 04 | B13: Fathia Boufalgha | C13: FATHIA BOUFALGHA | E13: titiprestige75@gmail.com | G13: +33759625661 | I13: =IF(B13="", "", IF(OR(C13="", C13="—"), 0, IFNA(XLOOKUP(C13, DATA_UBER!A:A, DATA_UBER!Z:Z, 0), 0))) -> 159.89 | J13: =IF(B13="", "", IF(OR(C13="", C13="—"), 0, IFNA(XLOOKUP(C13, DATA_UBER!A:A, DATA_UBER!J:J, 0), 0))) -> 0 | K13: =IF(B13="", "", IF(OR(D13="", D13="—"), 0, IFNA(XLOOKUP(D13, DATA_BOLT!A:A, DATA_BOLT!Z:Z, 0), 0))) -> 0 | L13: =IF(B13="", "", IF(OR(D13="", D13="—"), 0, IFNA(XLOOKUP(D13, DATA_BOLT!A:A, DATA_BOLT!G:G, 0), 0))) -> 0 | M13: =IF(B13="", "", I13 + K13) -> 159.89 | N13: =IF(B13="", "", IF(OR(I13<>0, K13<>0, J13<>0, L13<>0), IFNA(XLOOKUP(B13, ANNUAIRE_FLOTTE!B:B, ANNUAIRE_FLOTTE!J:J, 50), 50), 0)) -> 50 | O13: 137.5 | P13: 0 | Q13: 0 | R13: =IF(B13="", "", M13 - N13 - O13 - Q13 + P13) -> -27.61
A14: 05 | B14: Rachid Chinoune | C14: rachid CHINOUNE | D14: Rachid Chinoune | E14: rachidchinoune@yahoo.fr | F14: crtp2023@gmail.com | G14: +33619305126 | H14: +33619305126 | I14: =IF(B14="", "", IF(OR(C14="", C14="—"), 0, IFNA(XLOOKUP(C14, DATA_UBER!A:A, DATA_UBER!Z:Z, 0), 0))) -> 68.55 | J14: =IF(B14="", "", IF(OR(C14="", C14="—"), 0, IFNA(XLOOKUP(C14, DATA_UBER!A:A, DATA_UBER!J:J, 0), 0))) -> 0 | K14: =IF(B14="", "", IF(OR(D14="", D14="—"), 0, IFNA(XLOOKUP(D14, DATA_BOLT!A:A, DATA_BOLT!Z:Z, 0), 0))) -> 50.92 | L14: =IF(B14="", "", IF(OR(D14="", D14="—"), 0, IFNA(XLOOKUP(D14, DATA_BOLT!A:A, DATA_BOLT!G:G, 0), 0))) -> 0 | M14: =IF(B14="", "", I14 + K14) -> 119.47 | N14: =IF(B14="", "", IF(OR(I14<>0, K14<>0, J14<>0, L14<>0), IFNA(XLOOKUP(B14, ANNUAIRE_FLOTTE!B:B, ANNUAIRE_FLOTTE!J:J, 50), 50), 0)) -> 50 | O14: 0 | P14: 0 | Q14: 0 | R14: =IF(B14="", "", M14 - N14 - O14 - Q14 + P14) -> 69.47
A15: 06 | B15: Salah Fitouri | C15: Salah Fitouri | E15: Salih071@live.fr | G15: +33627393006 | I15: =IF(B15="", "", IF(OR(C15="", C15="—"), 0, IFNA(XLOOKUP(C15, DATA_UBER!A:A, DATA_UBER!Z:Z, 0), 0))) -> 0 | J15: =IF(B15="", "", IF(OR(C15="", C15="—"), 0, IFNA(XLOOKUP(C15, DATA_UBER!A:A, DATA_UBER!J:J, 0), 0))) -> 0 | K15: =IF(B15="", "", IF(OR(D15="", D15="—"), 0, IFNA(XLOOKUP(D15, DATA_BOLT!A:A, DATA_BOLT!Z:Z, 0), 0))) -> 0 | L15: =IF(B15="", "", IF(OR(D15="", D15="—"), 0, IFNA(XLOOKUP(D15, DATA_BOLT!A:A, DATA_BOLT!G:G, 0), 0))) -> 0 | M15: =IF(B15="", "", I15 + K15) -> 0 | N15: =IF(B15="", "", IF(OR(I15<>0, K15<>0, J15<>0, L15<>0), IFNA(XLOOKUP(B15, ANNUAIRE_FLOTTE!B:B, ANNUAIRE_FLOTTE!J:J, 50), 50), 0)) -> 0 | O15: 0 | P15: 0 | Q15: 0 | R15: =IF(B15="", "", M15 - N15 - O15 - Q15 + P15) -> 0
A16: 07 | B16: Bouchaib Belkharras | C16: Bouchaib Belkharras | D16: Bouchaïb Belkharras | E16: belbouch92@gmail.com | F16: bouch.bb@hotmail.com | G16: +33658123002 | H16: +33658123002 | I16: =IF(B16="", "", IF(OR(C16="", C16="—"), 0, IFNA(XLOOKUP(C16, DATA_UBER!A:A, DATA_UBER!Z:Z, 0), 0))) -> 0 | J16: =IF(B16="", "", IF(OR(C16="", C16="—"), 0, IFNA(XLOOKUP(C16, DATA_UBER!A:A, DATA_UBER!J:J, 0), 0))) -> 0 | K16: =IF(B16="", "", IF(OR(D16="", D16="—"), 0, IFNA(XLOOKUP(D16, DATA_BOLT!A:A, DATA_BOLT!Z:Z, 0), 0))) -> 350.58 | L16: =IF(B16="", "", IF(OR(D16="", D16="—"), 0, IFNA(XLOOKUP(D16, DATA_BOLT!A:A, DATA_BOLT!G:G, 0), 0))) -> 136.7 | M16: =IF(B16="", "", I16 + K16) -> 350.58 | N16: =IF(B16="", "", IF(OR(I16<>0, K16<>0, J16<>0, L16<>0), IFNA(XLOOKUP(B16, ANNUAIRE_FLOTTE!B:B, ANNUAIRE_FLOTTE!J:J, 50), 50), 0)) -> 60 | O16: 0 | P16: 0 | Q16: 0 | R16: =IF(B16="", "", M16 - N16 - O16 - Q16 + P16) -> 290.58
A17: 08 | B17: Brandon Jean Jimmy Louissaint | C17: BRANDON JEAN-JIMMY LOUISSAINT | D17: Brandon Jean Jimmy Louissaint | E17: louissaintbrandon@hotmail.com | F17: louissaintbrandon@hotmail.com | G17: +33635481157 | H17: +33635481157 | I17: =IF(B17="", "", IF(OR(C17="", C17="—"), 0, IFNA(XLOOKUP(C17, DATA_UBER!A:A, DATA_UBER!Z:Z, 0), 0))) -> 0 | J17: =IF(B17="", "", IF(OR(C17="", C17="—"), 0, IFNA(XLOOKUP(C17, DATA_UBER!A:A, DATA_UBER!J:J, 0), 0))) -> 0 | K17: =IF(B17="", "", IF(OR(D17="", D17="—"), 0, IFNA(XLOOKUP(D17, DATA_BOLT!A:A, DATA_BOLT!Z:Z, 0), 0))) -> 330.54 | L17: =IF(B17="", "", IF(OR(D17="", D17="—"), 0, IFNA(XLOOKUP(D17, DATA_BOLT!A:A, DATA_BOLT!G:G, 0), 0))) -> 334.8 | M17: =IF(B17="", "", I17 + K17) -> 330.54 | N17: =IF(B17="", "", IF(OR(I17<>0, K17<>0, J17<>0, L17<>0), IFNA(XLOOKUP(B17, ANNUAIRE_FLOTTE!B:B, ANNUAIRE_FLOTTE!J:J, 50), 50), 0)) -> 60 | O17: 0 | P17: 0 | Q17: 0 | R17: =IF(B17="", "", M17 - N17 - O17 - Q17 + P17) -> 270.54
A18: 09 | B18: Farid Adkhis | C18: Farid Adkhis | D18: Farid Adkhis | E18: Farid.adk@gmail.com | F18: Farid.adk@gmail.com | G18: +33651950695 | H18: +33651950695 | I18: =IF(B18="", "", IF(OR(C18="", C18="—"), 0, IFNA(XLOOKUP(C18, DATA_UBER!A:A, DATA_UBER!Z:Z, 0), 0))) -> 0 | J18: =IF(B18="", "", IF(OR(C18="", C18="—"), 0, IFNA(XLOOKUP(C18, DATA_UBER!A:A, DATA_UBER!J:J, 0), 0))) -> 0 | K18: =IF(B18="", "", IF(OR(D18="", D18="—"), 0, IFNA(XLOOKUP(D18, DATA_BOLT!A:A, DATA_BOLT!Z:Z, 0), 0))) -> 0 | L18: =IF(B18="", "", IF(OR(D18="", D18="—"), 0, IFNA(XLOOKUP(D18, DATA_BOLT!A:A, DATA_BOLT!G:G, 0), 0))) -> 0 | M18: =IF(B18="", "", I18 + K18) -> 0 | N18: =IF(B18="", "", IF(OR(I18<>0, K18<>0, J18<>0, L18<>0), IFNA(XLOOKUP(B18, ANNUAIRE_FLOTTE!B:B, ANNUAIRE_FLOTTE!J:J, 50), 50), 0)) -> 0 | O18: 0 | P18: 0 | Q18: 0 | R18: =IF(B18="", "", M18 - N18 - O18 - Q18 + P18) -> 0
A19: 10 | B19: Imane Sarraj | C19: Imane Sarraj | D19: Imane Sarraj | E19: imane.sar2009@gmail.com | F19: imane.sar2009@gmail.com | G19: +33658430022 | H19: +33658430022 | I19: =IF(B19="", "", IF(OR(C19="", C19="—"), 0, IFNA(XLOOKUP(C19, DATA_UBER!A:A, DATA_UBER!Z:Z, 0), 0))) -> 159.28 | J19: =IF(B19="", "", IF(OR(C19="", C19="—"), 0, IFNA(XLOOKUP(C19, DATA_UBER!A:A, DATA_UBER!J:J, 0), 0))) -> 0 | K19: =IF(B19="", "", IF(OR(D19="", D19="—"), 0, IFNA(XLOOKUP(D19, DATA_BOLT!A:A, DATA_BOLT!Z:Z, 0), 0))) -> 182.63 | L19: =IF(B19="", "", IF(OR(D19="", D19="—"), 0, IFNA(XLOOKUP(D19, DATA_BOLT!A:A, DATA_BOLT!G:G, 0), 0))) -> 95 | M19: =IF(B19="", "", I19 + K19) -> 341.91 | N19: =IF(B19="", "", IF(OR(I19<>0, K19<>0, J19<>0, L19<>0), IFNA(XLOOKUP(B19, ANNUAIRE_FLOTTE!B:B, ANNUAIRE_FLOTTE!J:J, 50), 50), 0)) -> 60 | O19: 0 | P19: 0 | Q19: 0 | R19: =IF(B19="", "", M19 - N19 - O19 - Q19 + P19) -> 281.91
A20: 11 | B20: Mehmet Ergun | C20: MEHMET ERGUN | D20: Mehmet Ergun | E20: mht.egn1@icloud.com | F20: Mht.Egn1@icloud.com | G20: +33782313002 | H20: +33782313002 | I20: =IF(B20="", "", IF(OR(C20="", C20="—"), 0, IFNA(XLOOKUP(C20, DATA_UBER!A:A, DATA_UBER!Z:Z, 0), 0))) -> 44.43 | J20: =IF(B20="", "", IF(OR(C20="", C20="—"), 0, IFNA(XLOOKUP(C20, DATA_UBER!A:A, DATA_UBER!J:J, 0), 0))) -> 0 | K20: =IF(B20="", "", IF(OR(D20="", D20="—"), 0, IFNA(XLOOKUP(D20, DATA_BOLT!A:A, DATA_BOLT!Z:Z, 0), 0))) -> 249.5 | L20: =IF(B20="", "", IF(OR(D20="", D20="—"), 0, IFNA(XLOOKUP(D20, DATA_BOLT!A:A, DATA_BOLT!G:G, 0), 0))) -> 90.3 | M20: =IF(B20="", "", I20 + K20) -> 293.93 | N20: =IF(B20="", "", IF(OR(I20<>0, K20<>0, J20<>0, L20<>0), IFNA(XLOOKUP(B20, ANNUAIRE_FLOTTE!B:B, ANNUAIRE_FLOTTE!J:J, 50), 50), 0)) -> 60 | O20: 0 | P20: 0 | Q20: 0 | R20: =IF(B20="", "", M20 - N20 - O20 - Q20 + P20) -> 233.93
A21: 12 | B21: Mohamed Aloui | C21: MOHAMED ALOUi | D21: Mohamed Aloui | E21: fainflash@hotmail.com | F21: Fainflash@hotmail.com | G21: +33762769951 | H21: +33762769951 | I21: =IF(B21="", "", IF(OR(C21="", C21="—"), 0, IFNA(XLOOKUP(C21, DATA_UBER!A:A, DATA_UBER!Z:Z, 0), 0))) -> 0 | J21: =IF(B21="", "", IF(OR(C21="", C21="—"), 0, IFNA(XLOOKUP(C21, DATA_UBER!A:A, DATA_UBER!J:J, 0), 0))) -> 0 | K21: =IF(B21="", "", IF(OR(D21="", D21="—"), 0, IFNA(XLOOKUP(D21, DATA_BOLT!A:A, DATA_BOLT!Z:Z, 0), 0))) -> 551.91 | L21: =IF(B21="", "", IF(OR(D21="", D21="—"), 0, IFNA(XLOOKUP(D21, DATA_BOLT!A:A, DATA_BOLT!G:G, 0), 0))) -> 137.3 | M21: =IF(B21="", "", I21 + K21) -> 551.91 | N21: =IF(B21="", "", IF(OR(I21<>0, K21<>0, J21<>0, L21<>0), IFNA(XLOOKUP(B21, ANNUAIRE_FLOTTE!B:B, ANNUAIRE_FLOTTE!J:J, 50), 50), 0)) -> 60 | O21: 0 | P21: 0 | Q21: 0 | R21: =IF(B21="", "", M21 - N21 - O21 - Q21 + P21) -> 491.91
A22: 13 | B22: Omar Chemkhi | C22: Omar Chemkhi | E22: omarchemkhioc@gmail.com | G22: +33783433834 | I22: =IF(B22="", "", IF(OR(C22="", C22="—"), 0, IFNA(XLOOKUP(C22, DATA_UBER!A:A, DATA_UBER!Z:Z, 0), 0))) -> 0 | J22: =IF(B22="", "", IF(OR(C22="", C22="—"), 0, IFNA(XLOOKUP(C22, DATA_UBER!A:A, DATA_UBER!J:J, 0), 0))) -> 0 | K22: =IF(B22="", "", IF(OR(D22="", D22="—"), 0, IFNA(XLOOKUP(D22, DATA_BOLT!A:A, DATA_BOLT!Z:Z, 0), 0))) -> 0 | L22: =IF(B22="", "", IF(OR(D22="", D22="—"), 0, IFNA(XLOOKUP(D22, DATA_BOLT!A:A, DATA_BOLT!G:G, 0), 0))) -> 0 | M22: =IF(B22="", "", I22 + K22) -> 0 | N22: =IF(B22="", "", IF(OR(I22<>0, K22<>0, J22<>0, L22<>0), IFNA(XLOOKUP(B22, ANNUAIRE_FLOTTE!B:B, ANNUAIRE_FLOTTE!J:J, 50), 50), 0)) -> 0 | O22: 0 | P22: 0 | Q22: 0 | R22: =IF(B22="", "", M22 - N22 - O22 - Q22 + P22) -> 0
A23: 14 | B23: Raoul Mansfeld Bemma | C23: Raoul Mansfeld Bemma | D23: Raoul Mansfeld Bemma | E23: raoulbemma0@gmail.com | F23: bemra@hotmail.fr | G23: +33672345507 | H23: +33672345507 | I23: =IF(B23="", "", IF(OR(C23="", C23="—"), 0, IFNA(XLOOKUP(C23, DATA_UBER!A:A, DATA_UBER!Z:Z, 0), 0))) -> 0 | J23: =IF(B23="", "", IF(OR(C23="", C23="—"), 0, IFNA(XLOOKUP(C23, DATA_UBER!A:A, DATA_UBER!J:J, 0), 0))) -> 0 | K23: =IF(B23="", "", IF(OR(D23="", D23="—"), 0, IFNA(XLOOKUP(D23, DATA_BOLT!A:A, DATA_BOLT!Z:Z, 0), 0))) -> 0 | L23: =IF(B23="", "", IF(OR(D23="", D23="—"), 0, IFNA(XLOOKUP(D23, DATA_BOLT!A:A, DATA_BOLT!G:G, 0), 0))) -> 0 | M23: =IF(B23="", "", I23 + K23) -> 0 | N23: =IF(B23="", "", IF(OR(I23<>0, K23<>0, J23<>0, L23<>0), IFNA(XLOOKUP(B23, ANNUAIRE_FLOTTE!B:B, ANNUAIRE_FLOTTE!J:J, 50), 50), 0)) -> 0 | O23: 0 | P23: 0 | Q23: 0 | R23: =IF(B23="", "", M23 - N23 - O23 - Q23 + P23) -> 0
A24: 15 | B24: Ratiba Beldjoudi | C24: Ratiba Beldjoudi | D24: Ratiba GUESRI | E24: amir2014bba@hotmail.com | F24: beldjoudilina@hotmail.fr | G24: +33695084256 | H24: +33695084256 | I24: =IF(B24="", "", IF(OR(C24="", C24="—"), 0, IFNA(XLOOKUP(C24, DATA_UBER!A:A, DATA_UBER!Z:Z, 0), 0))) -> 9.28 | J24: =IF(B24="", "", IF(OR(C24="", C24="—"), 0, IFNA(XLOOKUP(C24, DATA_UBER!A:A, DATA_UBER!J:J, 0), 0))) -> 0 | K24: =IF(B24="", "", IF(OR(D24="", D24="—"), 0, IFNA(XLOOKUP(D24, DATA_BOLT!A:A, DATA_BOLT!Z:Z, 0), 0))) -> 160.85 | L24: =IF(B24="", "", IF(OR(D24="", D24="—"), 0, IFNA(XLOOKUP(D24, DATA_BOLT!A:A, DATA_BOLT!G:G, 0), 0))) -> 625 | M24: =IF(B24="", "", I24 + K24) -> 170.13 | N24: =IF(B24="", "", IF(OR(I24<>0, K24<>0, J24<>0, L24<>0), IFNA(XLOOKUP(B24, ANNUAIRE_FLOTTE!B:B, ANNUAIRE_FLOTTE!J:J, 50), 50), 0)) -> 60 | O24: 0 | P24: 0 | Q24: 0 | R24: =IF(B24="", "", M24 - N24 - O24 - Q24 + P24) -> 110.13
A25: 16 | B25: Zahia Guesri | C25: Zahia Guesri | D25: Zahia Guesri | E25: c_zahwa@hotmail.com | F25: zaza.guess@hotmail.fr | G25: +33669354856 | H25: +33669354856 | I25: =IF(B25="", "", IF(OR(C25="", C25="—"), 0, IFNA(XLOOKUP(C25, DATA_UBER!A:A, DATA_UBER!Z:Z, 0), 0))) -> 0 | J25: =IF(B25="", "", IF(OR(C25="", C25="—"), 0, IFNA(XLOOKUP(C25, DATA_UBER!A:A, DATA_UBER!J:J, 0), 0))) -> 0 | K25: =IF(B25="", "", IF(OR(D25="", D25="—"), 0, IFNA(XLOOKUP(D25, DATA_BOLT!A:A, DATA_BOLT!Z:Z, 0), 0))) -> 142.12 | L25: =IF(B25="", "", IF(OR(D25="", D25="—"), 0, IFNA(XLOOKUP(D25, DATA_BOLT!A:A, DATA_BOLT!G:G, 0), 0))) -> 206.9 | M25: =IF(B25="", "", I25 + K25) -> 142.12 | N25: =IF(B25="", "", IF(OR(I25<>0, K25<>0, J25<>0, L25<>0), IFNA(XLOOKUP(B25, ANNUAIRE_FLOTTE!B:B, ANNUAIRE_FLOTTE!J:J, 50), 50), 0)) -> 60 | O25: 0 | P25: 0 | Q25: 0 | R25: =IF(B25="", "", M25 - N25 - O25 - Q25 + P25) -> 82.12
A26: 17 | B26: Abdel Mouamane Chelaif | C26: Abdel Mouamane Chelaif | D26: Abdel Mouamane CHELAIF | E26: chelaifmoumen@gmail.com | F26: chelaifmoumen@gmail.com | G26: +33753606026 | H26: +33753606026 | I26: =IF(B26="", "", IF(OR(C26="", C26="—"), 0, IFNA(XLOOKUP(C26, DATA_UBER!A:A, DATA_UBER!Z:Z, 0), 0))) -> 0 | J26: =IF(B26="", "", IF(OR(C26="", C26="—"), 0, IFNA(XLOOKUP(C26, DATA_UBER!A:A, DATA_UBER!J:J, 0), 0))) -> 0 | K26: =IF(B26="", "", IF(OR(D26="", D26="—"), 0, IFNA(XLOOKUP(D26, DATA_BOLT!A:A, DATA_BOLT!Z:Z, 0), 0))) -> 0 | L26: =IF(B26="", "", IF(OR(D26="", D26="—"), 0, IFNA(XLOOKUP(D26, DATA_BOLT!A:A, DATA_BOLT!G:G, 0), 0))) -> 0 | M26: =IF(B26="", "", I26 + K26) -> 0 | N26: =IF(B26="", "", IF(OR(I26<>0, K26<>0, J26<>0, L26<>0), IFNA(XLOOKUP(B26, ANNUAIRE_FLOTTE!B:B, ANNUAIRE_FLOTTE!J:J, 50), 50), 0)) -> 0 | O26: 0 | P26: 0 | Q26: 0 | R26: =IF(B26="", "", M26 - N26 - O26 - Q26 + P26) -> 0
A27: 18 | B27: Abdelaziz Guerfi | C27: Abdelaziz Guerfi | E27: guerfiaziz75@gmail.com | G27: +33671648042 | I27: =IF(B27="", "", IF(OR(C27="", C27="—"), 0, IFNA(XLOOKUP(C27, DATA_UBER!A:A, DATA_UBER!Z:Z, 0), 0))) -> 170.09 | J27: =IF(B27="", "", IF(OR(C27="", C27="—"), 0, IFNA(XLOOKUP(C27, DATA_UBER!A:A, DATA_UBER!J:J, 0), 0))) -> 50.95 | K27: =IF(B27="", "", IF(OR(D27="", D27="—"), 0, IFNA(XLOOKUP(D27, DATA_BOLT!A:A, DATA_BOLT!Z:Z, 0), 0))) -> 0 | L27: =IF(B27="", "", IF(OR(D27="", D27="—"), 0, IFNA(XLOOKUP(D27, DATA_BOLT!A:A, DATA_BOLT!G:G, 0), 0))) -> 0 | M27: =IF(B27="", "", I27 + K27) -> 170.09 | N27: =IF(B27="", "", IF(OR(I27<>0, K27<>0, J27<>0, L27<>0), IFNA(XLOOKUP(B27, ANNUAIRE_FLOTTE!B:B, ANNUAIRE_FLOTTE!J:J, 50), 50), 0)) -> 50 | O27: 0 | P27: 0 | Q27: 0 | R27: =IF(B27="", "", M27 - N27 - O27 - Q27 + P27) -> 120.09
A28: 19 | B28: Abdullah Kartal | C28: Abdullah Kartal | D28: Abdullah Kartal | E28: abdullahkartal@outlook.fr | F28: abdullahkartal@outlook.fr | G28: +33782374844 | H28: +33782374844 | I28: =IF(B28="", "", IF(OR(C28="", C28="—"), 0, IFNA(XLOOKUP(C28, DATA_UBER!A:A, DATA_UBER!Z:Z, 0), 0))) -> 0 | J28: =IF(B28="", "", IF(OR(C28="", C28="—"), 0, IFNA(XLOOKUP(C28, DATA_UBER!A:A, DATA_UBER!J:J, 0), 0))) -> 0 | K28: =IF(B28="", "", IF(OR(D28="", D28="—"), 0, IFNA(XLOOKUP(D28, DATA_BOLT!A:A, DATA_BOLT!Z:Z, 0), 0))) -> 0 | L28: =IF(B28="", "", IF(OR(D28="", D28="—"), 0, IFNA(XLOOKUP(D28, DATA_BOLT!A:A, DATA_BOLT!G:G, 0), 0))) -> 0 | M28: =IF(B28="", "", I28 + K28) -> 0 | N28: =IF(B28="", "", IF(OR(I28<>0, K28<>0, J28<>0, L28<>0), IFNA(XLOOKUP(B28, ANNUAIRE_FLOTTE!B:B, ANNUAIRE_FLOTTE!J:J, 50), 50), 0)) -> 0 | O28: 0 | P28: 0 | Q28: 0 | R28: =IF(B28="", "", M28 - N28 - O28 - Q28 + P28) -> 0
A29: 20 | B29: Adam Machtou | C29: Adam MACHTOU | D29: Adam Machtou | E29: machtou.adam@gmail.com | F29: machtou.adam@gmail.com | G29: +33618757203 | H29: +33618757203 | I29: =IF(B29="", "", IF(OR(C29="", C29="—"), 0, IFNA(XLOOKUP(C29, DATA_UBER!A:A, DATA_UBER!Z:Z, 0), 0))) -> 0 | J29: =IF(B29="", "", IF(OR(C29="", C29="—"), 0, IFNA(XLOOKUP(C29, DATA_UBER!A:A, DATA_UBER!J:J, 0), 0))) -> 0 | K29: =IF(B29="", "", IF(OR(D29="", D29="—"), 0, IFNA(XLOOKUP(D29, DATA_BOLT!A:A, DATA_BOLT!Z:Z, 0), 0))) -> 137.12 | L29: =IF(B29="", "", IF(OR(D29="", D29="—"), 0, IFNA(XLOOKUP(D29, DATA_BOLT!A:A, DATA_BOLT!G:G, 0), 0))) -> 12 | M29: =IF(B29="", "", I29 + K29) -> 137.12 | N29: =IF(B29="", "", IF(OR(I29<>0, K29<>0, J29<>0, L29<>0), IFNA(XLOOKUP(B29, ANNUAIRE_FLOTTE!B:B, ANNUAIRE_FLOTTE!J:J, 50), 50), 0)) -> 50 | O29: 0 | P29: 0 | Q29: 0 | R29: =IF(B29="", "", M29 - N29 - O29 - Q29 + P29) -> 87.12
A30: 21 | B30: Adel Benabdelouahed | C30: ADEL BENABDELOUAHED | D30: Mohammed Adel benabdelouahed | E30: adelbenan@gmail.com | F30: adelbenan@gmail.com | G30: +33782790937 | H30: +33782790937 | I30: =IF(B30="", "", IF(OR(C30="", C30="—"), 0, IFNA(XLOOKUP(C30, DATA_UBER!A:A, DATA_UBER!Z:Z, 0), 0))) -> 37.47 | J30: =IF(B30="", "", IF(OR(C30="", C30="—"), 0, IFNA(XLOOKUP(C30, DATA_UBER!A:A, DATA_UBER!J:J, 0), 0))) -> 0 | K30: =IF(B30="", "", IF(OR(D30="", D30="—"), 0, IFNA(XLOOKUP(D30, DATA_BOLT!A:A, DATA_BOLT!Z:Z, 0), 0))) -> 230.37 | L30: =IF(B30="", "", IF(OR(D30="", D30="—"), 0, IFNA(XLOOKUP(D30, DATA_BOLT!A:A, DATA_BOLT!G:G, 0), 0))) -> 66.3 | M30: =IF(B30="", "", I30 + K30) -> 267.84 | N30: =IF(B30="", "", IF(OR(I30<>0, K30<>0, J30<>0, L30<>0), IFNA(XLOOKUP(B30, ANNUAIRE_FLOTTE!B:B, ANNUAIRE_FLOTTE!J:J, 50), 50), 0)) -> 50 | O30: 0 | P30: 0 | Q30: 0 | R30: =IF(B30="", "", M30 - N30 - O30 - Q30 + P30) -> 217.84
A31: 22 | B31: Ahmed Kherfouche | C31: Ahmed Kherfouche | E31: cena2309@hotmail.fr | G31: +33612943281 | I31: =IF(B31="", "", IF(OR(C31="", C31="—"), 0, IFNA(XLOOKUP(C31, DATA_UBER!A:A, DATA_UBER!Z:Z, 0), 0))) -> 0 | J31: =IF(B31="", "", IF(OR(C31="", C31="—"), 0, IFNA(XLOOKUP(C31, DATA_UBER!A:A, DATA_UBER!J:J, 0), 0))) -> 0 | K31: =IF(B31="", "", IF(OR(D31="", D31="—"), 0, IFNA(XLOOKUP(D31, DATA_BOLT!A:A, DATA_BOLT!Z:Z, 0), 0))) -> 0 | L31: =IF(B31="", "", IF(OR(D31="", D31="—"), 0, IFNA(XLOOKUP(D31, DATA_BOLT!A:A, DATA_BOLT!G:G, 0), 0))) -> 0 | M31: =IF(B31="", "", I31 + K31) -> 0 | N31: =IF(B31="", "", IF(OR(I31<>0, K31<>0, J31<>0, L31<>0), IFNA(XLOOKUP(B31, ANNUAIRE_FLOTTE!B:B, ANNUAIRE_FLOTTE!J:J, 50), 50), 0)) -> 0 | O31: 0 | P31: 0 | Q31: 0 | R31: =IF(B31="", "", M31 - N31 - O31 - Q31 + P31) -> 0
A32: 23 | B32: Alhassane Balde | C32: Alhassane Balde | D32: Alhassane Balde | E32: alh.balde05@gmail.com | F32: alh.balde05@gmail.com | G32: +33783639299 | H32: +33783639299 | I32: =IF(B32="", "", IF(OR(C32="", C32="—"), 0, IFNA(XLOOKUP(C32, DATA_UBER!A:A, DATA_UBER!Z:Z, 0), 0))) -> 118.18 | J32: =IF(B32="", "", IF(OR(C32="", C32="—"), 0, IFNA(XLOOKUP(C32, DATA_UBER!A:A, DATA_UBER!J:J, 0), 0))) -> 0 | K32: =IF(B32="", "", IF(OR(D32="", D32="—"), 0, IFNA(XLOOKUP(D32, DATA_BOLT!A:A, DATA_BOLT!Z:Z, 0), 0))) -> -2.56 | L32: =IF(B32="", "", IF(OR(D32="", D32="—"), 0, IFNA(XLOOKUP(D32, DATA_BOLT!A:A, DATA_BOLT!G:G, 0), 0))) -> 16.7 | M32: =IF(B32="", "", I32 + K32) -> 115.62 | N32: =IF(B32="", "", IF(OR(I32<>0, K32<>0, J32<>0, L32<>0), IFNA(XLOOKUP(B32, ANNUAIRE_FLOTTE!B:B, ANNUAIRE_FLOTTE!J:J, 50), 50), 0)) -> 50 | O32: 0 | P32: 0 | Q32: 0 | R32: =IF(B32="", "", M32 - N32 - O32 - Q32 + P32) -> 65.62
A33: 24 | B33: Ali Alouani | C33: Ali Alouani | D33: Ali Alouani | E33: ali.alouani.95@gmail.com | F33: ali.alouani.95@gmail.com | G33: +33618122054 | H33: +33618122054 | I33: =IF(B33="", "", IF(OR(C33="", C33="—"), 0, IFNA(XLOOKUP(C33, DATA_UBER!A:A, DATA_UBER!Z:Z, 0), 0))) -> 0 | J33: =IF(B33="", "", IF(OR(C33="", C33="—"), 0, IFNA(XLOOKUP(C33, DATA_UBER!A:A, DATA_UBER!J:J, 0), 0))) -> 0 | K33: =IF(B33="", "", IF(OR(D33="", D33="—"), 0, IFNA(XLOOKUP(D33, DATA_BOLT!A:A, DATA_BOLT!Z:Z, 0), 0))) -> 408.54 | L33: =IF(B33="", "", IF(OR(D33="", D33="—"), 0, IFNA(XLOOKUP(D33, DATA_BOLT!A:A, DATA_BOLT!G:G, 0), 0))) -> 246.3 | M33: =IF(B33="", "", I33 + K33) -> 408.54 | N33: =IF(B33="", "", IF(OR(I33<>0, K33<>0, J33<>0, L33<>0), IFNA(XLOOKUP(B33, ANNUAIRE_FLOTTE!B:B, ANNUAIRE_FLOTTE!J:J, 50), 50), 0)) -> 50 | O33: 0 | P33: 0 | Q33: 0 | R33: =IF(B33="", "", M33 - N33 - O33 - Q33 + P33) -> 358.54
A34: 25 | B34: Asma Kissi | C34: ASMA KISSI | E34: kissiasma333@gmail.com | G34: +33626907046 | I34: =IF(B34="", "", IF(OR(C34="", C34="—"), 0, IFNA(XLOOKUP(C34, DATA_UBER!A:A, DATA_UBER!Z:Z, 0), 0))) -> 0 | J34: =IF(B34="", "", IF(OR(C34="", C34="—"), 0, IFNA(XLOOKUP(C34, DATA_UBER!A:A, DATA_UBER!J:J, 0), 0))) -> 0 | K34: =IF(B34="", "", IF(OR(D34="", D34="—"), 0, IFNA(XLOOKUP(D34, DATA_BOLT!A:A, DATA_BOLT!Z:Z, 0), 0))) -> 0 | L34: =IF(B34="", "", IF(OR(D34="", D34="—"), 0, IFNA(XLOOKUP(D34, DATA_BOLT!A:A, DATA_BOLT!G:G, 0), 0))) -> 0 | M34: =IF(B34="", "", I34 + K34) -> 0 | N34: =IF(B34="", "", IF(OR(I34<>0, K34<>0, J34<>0, L34<>0), IFNA(XLOOKUP(B34, ANNUAIRE_FLOTTE!B:B, ANNUAIRE_FLOTTE!J:J, 50), 50), 0)) -> 0 | O34: 0 | P34: 0 | Q34: 0 | R34: =IF(B34="", "", M34 - N34 - O34 - Q34 + P34) -> 0
A35: 26 | B35: Aymen Ltifi | C35: Aymen Ltifi | D35: Aymen Ltifi | E35: ltifiservices@outlook.com | F35: ltifiservices@outlook.com | G35: +33760731822 | H35: +33760731822 | I35: =IF(B35="", "", IF(OR(C35="", C35="—"), 0, IFNA(XLOOKUP(C35, DATA_UBER!A:A, DATA_UBER!Z:Z, 0), 0))) -> 0 | J35: =IF(B35="", "", IF(OR(C35="", C35="—"), 0, IFNA(XLOOKUP(C35, DATA_UBER!A:A, DATA_UBER!J:J, 0), 0))) -> 0 | K35: =IF(B35="", "", IF(OR(D35="", D35="—"), 0, IFNA(XLOOKUP(D35, DATA_BOLT!A:A, DATA_BOLT!Z:Z, 0), 0))) -> 11.44 | L35: =IF(B35="", "", IF(OR(D35="", D35="—"), 0, IFNA(XLOOKUP(D35, DATA_BOLT!A:A, DATA_BOLT!G:G, 0), 0))) -> 0 | M35: =IF(B35="", "", I35 + K35) -> 11.44 | N35: =IF(B35="", "", IF(OR(I35<>0, K35<>0, J35<>0, L35<>0), IFNA(XLOOKUP(B35, ANNUAIRE_FLOTTE!B:B, ANNUAIRE_FLOTTE!J:J, 50), 50), 0)) -> 50 | O35: 0 | P35: 0 | Q35: 0 | R35: =IF(B35="", "", M35 - N35 - O35 - Q35 + P35) -> -38.56
A36: 27 | B36: Bilel Bouhali | C36: Bilel Bouhali | E36: thecompany2275@gmail.com | G36: +33743767400 | I36: =IF(B36="", "", IF(OR(C36="", C36="—"), 0, IFNA(XLOOKUP(C36, DATA_UBER!A:A, DATA_UBER!Z:Z, 0), 0))) -> 0 | J36: =IF(B36="", "", IF(OR(C36="", C36="—"), 0, IFNA(XLOOKUP(C36, DATA_UBER!A:A, DATA_UBER!J:J, 0), 0))) -> 0 | K36: =IF(B36="", "", IF(OR(D36="", D36="—"), 0, IFNA(XLOOKUP(D36, DATA_BOLT!A:A, DATA_BOLT!Z:Z, 0), 0))) -> 0 | L36: =IF(B36="", "", IF(OR(D36="", D36="—"), 0, IFNA(XLOOKUP(D36, DATA_BOLT!A:A, DATA_BOLT!G:G, 0), 0))) -> 0 | M36: =IF(B36="", "", I36 + K36) -> 0 | N36: =IF(B36="", "", IF(OR(I36<>0, K36<>0, J36<>0, L36<>0), IFNA(XLOOKUP(B36, ANNUAIRE_FLOTTE!B:B, ANNUAIRE_FLOTTE!J:J, 50), 50), 0)) -> 0 | O36: 0 | P36: 0 | Q36: 0 | R36: =IF(B36="", "", M36 - N36 - O36 - Q36 + P36) -> 0
A37: 28 | B37: Brahim Aloui | C37: Brahim Aloui | D37: brahim aloui | E37: alouibrahim@ymail.com | F37: alouibrahim@ymail.com | G37: +33624959758 | H37: +33624959758 | I37: =IF(B37="", "", IF(OR(C37="", C37="—"), 0, IFNA(XLOOKUP(C37, DATA_UBER!A:A, DATA_UBER!Z:Z, 0), 0))) -> 0 | J37: =IF(B37="", "", IF(OR(C37="", C37="—"), 0, IFNA(XLOOKUP(C37, DATA_UBER!A:A, DATA_UBER!J:J, 0), 0))) -> 0 | K37: =IF(B37="", "", IF(OR(D37="", D37="—"), 0, IFNA(XLOOKUP(D37, DATA_BOLT!A:A, DATA_BOLT!Z:Z, 0), 0))) -> 0 | L37: =IF(B37="", "", IF(OR(D37="", D37="—"), 0, IFNA(XLOOKUP(D37, DATA_BOLT!A:A, DATA_BOLT!G:G, 0), 0))) -> 0 | M37: =IF(B37="", "", I37 + K37) -> 0 | N37: =IF(B37="", "", IF(OR(I37<>0, K37<>0, J37<>0, L37<>0), IFNA(XLOOKUP(B37, ANNUAIRE_FLOTTE!B:B, ANNUAIRE_FLOTTE!J:J, 50), 50), 0)) -> 0 | O37: 0 | P37: 0 | Q37: 0 | R37: =IF(B37="", "", M37 - N37 - O37 - Q37 + P37) -> 0
A38: 29 | B38: Bryan Grégory Michaud | C38: Bryan Grégory Michaud | D38: Bryan Gregory Michaud | E38: bryan.michaud11@gmail.com | F38: bryan.michaud11@gmail.com | G38: +33783633084 | H38: +33783633084 | I38: =IF(B38="", "", IF(OR(C38="", C38="—"), 0, IFNA(XLOOKUP(C38, DATA_UBER!A:A, DATA_UBER!Z:Z, 0), 0))) -> 0 | J38: =IF(B38="", "", IF(OR(C38="", C38="—"), 0, IFNA(XLOOKUP(C38, DATA_UBER!A:A, DATA_UBER!J:J, 0), 0))) -> 0 | K38: =IF(B38="", "", IF(OR(D38="", D38="—"), 0, IFNA(XLOOKUP(D38, DATA_BOLT!A:A, DATA_BOLT!Z:Z, 0), 0))) -> 0 | L38: =IF(B38="", "", IF(OR(D38="", D38="—"), 0, IFNA(XLOOKUP(D38, DATA_BOLT!A:A, DATA_BOLT!G:G, 0), 0))) -> 0 | M38: =IF(B38="", "", I38 + K38) -> 0 | N38: =IF(B38="", "", IF(OR(I38<>0, K38<>0, J38<>0, L38<>0), IFNA(XLOOKUP(B38, ANNUAIRE_FLOTTE!B:B, ANNUAIRE_FLOTTE!J:J, 50), 50), 0)) -> 0 | O38: 0 | P38: 0 | Q38: 0 | R38: =IF(B38="", "", M38 - N38 - O38 - Q38 + P38) -> 0
A39: 30 | B39: Christopher Andrew Mongis | C39: Christopher Andrew Mongis | E39: mongis.christopher77@gmail.com | G39: +33605838100 | I39: =IF(B39="", "", IF(OR(C39="", C39="—"), 0, IFNA(XLOOKUP(C39, DATA_UBER!A:A, DATA_UBER!Z:Z, 0), 0))) -> 179.99 | J39: =IF(B39="", "", IF(OR(C39="", C39="—"), 0, IFNA(XLOOKUP(C39, DATA_UBER!A:A, DATA_UBER!J:J, 0), 0))) -> 43.98 | K39: =IF(B39="", "", IF(OR(D39="", D39="—"), 0, IFNA(XLOOKUP(D39, DATA_BOLT!A:A, DATA_BOLT!Z:Z, 0), 0))) -> 0 | L39: =IF(B39="", "", IF(OR(D39="", D39="—"), 0, IFNA(XLOOKUP(D39, DATA_BOLT!A:A, DATA_BOLT!G:G, 0), 0))) -> 0 | M39: =IF(B39="", "", I39 + K39) -> 179.99 | N39: =IF(B39="", "", IF(OR(I39<>0, K39<>0, J39<>0, L39<>0), IFNA(XLOOKUP(B39, ANNUAIRE_FLOTTE!B:B, ANNUAIRE_FLOTTE!J:J, 50), 50), 0)) -> 50 | O39: 0 | P39: 0 | Q39: 0 | R39: =IF(B39="", "", M39 - N39 - O39 - Q39 + P39) -> 129.99
A40: 31 | B40: Daba Gandega | C40: Daba Gandega | E40: dg93240@hotmail.fr | G40: +33652830506 | I40: =IF(B40="", "", IF(OR(C40="", C40="—"), 0, IFNA(XLOOKUP(C40, DATA_UBER!A:A, DATA_UBER!Z:Z, 0), 0))) -> 0 | J40: =IF(B40="", "", IF(OR(C40="", C40="—"), 0, IFNA(XLOOKUP(C40, DATA_UBER!A:A, DATA_UBER!J:J, 0), 0))) -> 0 | K40: =IF(B40="", "", IF(OR(D40="", D40="—"), 0, IFNA(XLOOKUP(D40, DATA_BOLT!A:A, DATA_BOLT!Z:Z, 0), 0))) -> 0 | L40: =IF(B40="", "", IF(OR(D40="", D40="—"), 0, IFNA(XLOOKUP(D40, DATA_BOLT!A:A, DATA_BOLT!G:G, 0), 0))) -> 0 | M40: =IF(B40="", "", I40 + K40) -> 0 | N40: =IF(B40="", "", IF(OR(I40<>0, K40<>0, J40<>0, L40<>0), IFNA(XLOOKUP(B40, ANNUAIRE_FLOTTE!B:B, ANNUAIRE_FLOTTE!J:J, 50), 50), 0)) -> 0 | O40: 0 | P40: 0 | Q40: 0 | R40: =IF(B40="", "", M40 - N40 - O40 - Q40 + P40) -> 0
A41: 32 | B41: Elias Bihi | C41: ELIAS BIHI | D41: Elias Bihi | E41: bihieliaspro@gmail.com | F41: Bihieliaspro@gmail.com | G41: +33749483638 | H41: +33749483638 | I41: =IF(B41="", "", IF(OR(C41="", C41="—"), 0, IFNA(XLOOKUP(C41, DATA_UBER!A:A, DATA_UBER!Z:Z, 0), 0))) -> 0 | J41: =IF(B41="", "", IF(OR(C41="", C41="—"), 0, IFNA(XLOOKUP(C41, DATA_UBER!A:A, DATA_UBER!J:J, 0), 0))) -> 0 | K41: =IF(B41="", "", IF(OR(D41="", D41="—"), 0, IFNA(XLOOKUP(D41, DATA_BOLT!A:A, DATA_BOLT!Z:Z, 0), 0))) -> 254.45 | L41: =IF(B41="", "", IF(OR(D41="", D41="—"), 0, IFNA(XLOOKUP(D41, DATA_BOLT!A:A, DATA_BOLT!G:G, 0), 0))) -> 81.6 | M41: =IF(B41="", "", I41 + K41) -> 254.45 | N41: =IF(B41="", "", IF(OR(I41<>0, K41<>0, J41<>0, L41<>0), IFNA(XLOOKUP(B41, ANNUAIRE_FLOTTE!B:B, ANNUAIRE_FLOTTE!J:J, 50), 50), 0)) -> 50 | O41: 0 | P41: 0 | Q41: 0 | R41: =IF(B41="", "", M41 - N41 - O41 - Q41 + P41) -> 204.45
A42: 33 | B42: Elias Hocine Abdellou | C42: ELIAS HOCINE ABDELLOU | E42: eabdellou92@gmail.com | G42: +33676966368 | I42: =IF(B42="", "", IF(OR(C42="", C42="—"), 0, IFNA(XLOOKUP(C42, DATA_UBER!A:A, DATA_UBER!Z:Z, 0), 0))) -> 0 | J42: =IF(B42="", "", IF(OR(C42="", C42="—"), 0, IFNA(XLOOKUP(C42, DATA_UBER!A:A, DATA_UBER!J:J, 0), 0))) -> 0 | K42: =IF(B42="", "", IF(OR(D42="", D42="—"), 0, IFNA(XLOOKUP(D42, DATA_BOLT!A:A, DATA_BOLT!Z:Z, 0), 0))) -> 0 | L42: =IF(B42="", "", IF(OR(D42="", D42="—"), 0, IFNA(XLOOKUP(D42, DATA_BOLT!A:A, DATA_BOLT!G:G, 0), 0))) -> 0 | M42: =IF(B42="", "", I42 + K42) -> 0 | N42: =IF(B42="", "", IF(OR(I42<>0, K42<>0, J42<>0, L42<>0), IFNA(XLOOKUP(B42, ANNUAIRE_FLOTTE!B:B, ANNUAIRE_FLOTTE!J:J, 50), 50), 0)) -> 0 | O42: 0 | P42: 0 | Q42: 0 | R42: =IF(B42="", "", M42 - N42 - O42 - Q42 + P42) -> 0
A43: 34 | B43: Faical Jabri | C43: FAICAL JABRI | E43: faicaljabri@yahoo.fr | G43: +33625654846 | I43: =IF(B43="", "", IF(OR(C43="", C43="—"), 0, IFNA(XLOOKUP(C43, DATA_UBER!A:A, DATA_UBER!Z:Z, 0), 0))) -> 157.37 | J43: =IF(B43="", "", IF(OR(C43="", C43="—"), 0, IFNA(XLOOKUP(C43, DATA_UBER!A:A, DATA_UBER!J:J, 0), 0))) -> 29.9 | K43: =IF(B43="", "", IF(OR(D43="", D43="—"), 0, IFNA(XLOOKUP(D43, DATA_BOLT!A:A, DATA_BOLT!Z:Z, 0), 0))) -> 0 | L43: =IF(B43="", "", IF(OR(D43="", D43="—"), 0, IFNA(XLOOKUP(D43, DATA_BOLT!A:A, DATA_BOLT!G:G, 0), 0))) -> 0 | M43: =IF(B43="", "", I43 + K43) -> 157.37 | N43: =IF(B43="", "", IF(OR(I43<>0, K43<>0, J43<>0, L43<>0), IFNA(XLOOKUP(B43, ANNUAIRE_FLOTTE!B:B, ANNUAIRE_FLOTTE!J:J, 50), 50), 0)) -> 50 | O43: 0 | P43: 0 | Q43: 0 | R43: =IF(B43="", "", M43 - N43 - O43 - Q43 + P43) -> 107.37
...

Sheet EXPORT_QONTO
A1: beneficiary_name | B1: iban | C1: amount | D1: currency | E1: reference
A2: =IF(DASHBOARD_SEMAINE!B10="", "", DASHBOARD_SEMAINE!B10) -> Abdallah Hamzi | B2: =IF(DASHBOARD_SEMAINE!B10="", "", DASHBOARD_SEMAINE!S10) | C2: =IF(OR(DASHBOARD_SEMAINE!B10="", DASHBOARD_SEMAINE!R10<=0), "", ROUND(DASHBOARD_SEMAINE!R10, 2)) | D2: =IF(DASHBOARD_SEMAINE!B10="", "", "EUR") -> EUR | E2: =IF(DASHBOARD_SEMAINE!B10="", "", "Virement Semaine - " & DASHBOARD_SEMAINE!B10) -> Virement Semaine - Abdallah Hamzi
A3: =IF(DASHBOARD_SEMAINE!B11="", "", DASHBOARD_SEMAINE!B11) -> Abdoul Azize Mohamed Safir | B3: =IF(DASHBOARD_SEMAINE!B11="", "", DASHBOARD_SEMAINE!S11) | C3: =IF(OR(DASHBOARD_SEMAINE!B11="", DASHBOARD_SEMAINE!R11<=0), "", ROUND(DASHBOARD_SEMAINE!R11, 2)) -> 177.18 | D3: =IF(DASHBOARD_SEMAINE!B11="", "", "EUR") -> EUR | E3: =IF(DASHBOARD_SEMAINE!B11="", "", "Virement Semaine - " & DASHBOARD_SEMAINE!B11) -> Virement Semaine - Abdoul Azize Mohamed Safir
A4: =IF(DASHBOARD_SEMAINE!B12="", "", DASHBOARD_SEMAINE!B12) -> Bechir Ben Smida | B4: =IF(DASHBOARD_SEMAINE!B12="", "", DASHBOARD_SEMAINE!S12) | C4: =IF(OR(DASHBOARD_SEMAINE!B12="", DASHBOARD_SEMAINE!R12<=0), "", ROUND(DASHBOARD_SEMAINE!R12, 2)) -> 112.02 | D4: =IF(DASHBOARD_SEMAINE!B12="", "", "EUR") -> EUR | E4: =IF(DASHBOARD_SEMAINE!B12="", "", "Virement Semaine - " & DASHBOARD_SEMAINE!B12) -> Virement Semaine - Bechir Ben Smida
A5: =IF(DASHBOARD_SEMAINE!B13="", "", DASHBOARD_SEMAINE!B13) -> Fathia Boufalgha | B5: =IF(DASHBOARD_SEMAINE!B13="", "", DASHBOARD_SEMAINE!S13) | C5: =IF(OR(DASHBOARD_SEMAINE!B13="", DASHBOARD_SEMAINE!R13<=0), "", ROUND(DASHBOARD_SEMAINE!R13, 2)) | D5: =IF(DASHBOARD_SEMAINE!B13="", "", "EUR") -> EUR | E5: =IF(DASHBOARD_SEMAINE!B13="", "", "Virement Semaine - " & DASHBOARD_SEMAINE!B13) -> Virement Semaine - Fathia Boufalgha
A6: =IF(DASHBOARD_SEMAINE!B14="", "", DASHBOARD_SEMAINE!B14) -> Rachid Chinoune | B6: =IF(DASHBOARD_SEMAINE!B14="", "", DASHBOARD_SEMAINE!S14) | C6: =IF(OR(DASHBOARD_SEMAINE!B14="", DASHBOARD_SEMAINE!R14<=0), "", ROUND(DASHBOARD_SEMAINE!R14, 2)) -> 69.47 | D6: =IF(DASHBOARD_SEMAINE!B14="", "", "EUR") -> EUR | E6: =IF(DASHBOARD_SEMAINE!B14="", "", "Virement Semaine - " & DASHBOARD_SEMAINE!B14) -> Virement Semaine - Rachid Chinoune
A7: =IF(DASHBOARD_SEMAINE!B15="", "", DASHBOARD_SEMAINE!B15) -> Salah Fitouri | B7: =IF(DASHBOARD_SEMAINE!B15="", "", DASHBOARD_SEMAINE!S15) | C7: =IF(OR(DASHBOARD_SEMAINE!B15="", DASHBOARD_SEMAINE!R15<=0), "", ROUND(DASHBOARD_SEMAINE!R15, 2)) | D7: =IF(DASHBOARD_SEMAINE!B15="", "", "EUR") -> EUR | E7: =IF(DASHBOARD_SEMAINE!B15="", "", "Virement Semaine - " & DASHBOARD_SEMAINE!B15) -> Virement Semaine - Salah Fitouri
A8: =IF(DASHBOARD_SEMAINE!B16="", "", DASHBOARD_SEMAINE!B16) -> Bouchaib Belkharras | B8: =IF(DASHBOARD_SEMAINE!B16="", "", DASHBOARD_SEMAINE!S16) | C8: =IF(OR(DASHBOARD_SEMAINE!B16="", DASHBOARD_SEMAINE!R16<=0), "", ROUND(DASHBOARD_SEMAINE!R16, 2)) -> 290.58 | D8: =IF(DASHBOARD_SEMAINE!B16="", "", "EUR") -> EUR | E8: =IF(DASHBOARD_SEMAINE!B16="", "", "Virement Semaine - " & DASHBOARD_SEMAINE!B16) -> Virement Semaine - Bouchaib Belkharras
A9: =IF(DASHBOARD_SEMAINE!B17="", "", DASHBOARD_SEMAINE!B17) -> Brandon Jean Jimmy Louissaint | B9: =IF(DASHBOARD_SEMAINE!B17="", "", DASHBOARD_SEMAINE!S17) | C9: =IF(OR(DASHBOARD_SEMAINE!B17="", DASHBOARD_SEMAINE!R17<=0), "", ROUND(DASHBOARD_SEMAINE!R17, 2)) -> 270.54 | D9: =IF(DASHBOARD_SEMAINE!B17="", "", "EUR") -> EUR | E9: =IF(DASHBOARD_SEMAINE!B17="", "", "Virement Semaine - " & DASHBOARD_SEMAINE!B17) -> Virement Semaine - Brandon Jean Jimmy Louissaint
A10: =IF(DASHBOARD_SEMAINE!B18="", "", DASHBOARD_SEMAINE!B18) -> Farid Adkhis | B10: =IF(DASHBOARD_SEMAINE!B18="", "", DASHBOARD_SEMAINE!S18) | C10: =IF(OR(DASHBOARD_SEMAINE!B18="", DASHBOARD_SEMAINE!R18<=0), "", ROUND(DASHBOARD_SEMAINE!R18, 2)) | D10: =IF(DASHBOARD_SEMAINE!B18="", "", "EUR") -> EUR | E10: =IF(DASHBOARD_SEMAINE!B18="", "", "Virement Semaine - " & DASHBOARD_SEMAINE!B18) -> Virement Semaine - Farid Adkhis
A11: =IF(DASHBOARD_SEMAINE!B19="", "", DASHBOARD_SEMAINE!B19) -> Imane Sarraj | B11: =IF(DASHBOARD_SEMAINE!B19="", "", DASHBOARD_SEMAINE!S19) | C11: =IF(OR(DASHBOARD_SEMAINE!B19="", DASHBOARD_SEMAINE!R19<=0), "", ROUND(DASHBOARD_SEMAINE!R19, 2)) -> 281.91 | D11: =IF(DASHBOARD_SEMAINE!B19="", "", "EUR") -> EUR | E11: =IF(DASHBOARD_SEMAINE!B19="", "", "Virement Semaine - " & DASHBOARD_SEMAINE!B19) -> Virement Semaine - Imane Sarraj
A12: =IF(DASHBOARD_SEMAINE!B20="", "", DASHBOARD_SEMAINE!B20) -> Mehmet Ergun | B12: =IF(DASHBOARD_SEMAINE!B20="", "", DASHBOARD_SEMAINE!S20) | C12: =IF(OR(DASHBOARD_SEMAINE!B20="", DASHBOARD_SEMAINE!R20<=0), "", ROUND(DASHBOARD_SEMAINE!R20, 2)) -> 233.93 | D12: =IF(DASHBOARD_SEMAINE!B20="", "", "EUR") -> EUR | E12: =IF(DASHBOARD_SEMAINE!B20="", "", "Virement Semaine - " & DASHBOARD_SEMAINE!B20) -> Virement Semaine - Mehmet Ergun
A13: =IF(DASHBOARD_SEMAINE!B21="", "", DASHBOARD_SEMAINE!B21) -> Mohamed Aloui | B13: =IF(DASHBOARD_SEMAINE!B21="", "", DASHBOARD_SEMAINE!S21) | C13: =IF(OR(DASHBOARD_SEMAINE!B21="", DASHBOARD_SEMAINE!R21<=0), "", ROUND(DASHBOARD_SEMAINE!R21, 2)) -> 491.91 | D13: =IF(DASHBOARD_SEMAINE!B21="", "", "EUR") -> EUR | E13: =IF(DASHBOARD_SEMAINE!B21="", "", "Virement Semaine - " & DASHBOARD_SEMAINE!B21) -> Virement Semaine - Mohamed Aloui
... A73: =IF(DASHBOARD_SEMAINE!B81="", "", DASHBOARD_SEMAINE!B81) -> Raphaël Ernest Amié Vimond | B73: =IF(DASHBOARD_SEMAINE!B81="", "", DASHBOARD_SEMAINE!S81) | C73: =IF(OR(DASHBOARD_SEMAINE!B81="", DASHBOARD_SEMAINE!R81<=0), "", ROUND(DASHBOARD_SEMAINE!R81, 2)) | D73: =IF(DASHBOARD_SEMAINE!B81="", "", "EUR") -> EUR | E73: =IF(DASHBOARD_SEMAINE!B81="", "", "Virement Semaine - " & DASHBOARD_SEMAINE!B81) -> Virement Semaine - Raphaël Ernest Amié Vimond

Sheet 📁 S39 (21 au 27 Sept)
B1: FLEET OS — ARCHIVE OFFICIELLE SEMAINE 39 (69 CHAUFFEURS)
B2: Archive Figée — Période travaillée : 21 au 27 Septembre 2026 • Virement bancaire Qonto exécuté le : 28/09/2026
B4: TOTAL RÉEL ENCAISSÉ (UBER+BOLT) | F4: SUIVI ESPÈCES TOTALES (UBER+BOLT) | J4: REVENUS RATTACHEMENT FLOTTE | N4: TOTAL NET À VIRER (QONTO)
B5: 9963.33 | F5: 4673.84 | J5: 2310 | N5: 7358.33
A8: 👤 IDENTITÉ DU CHAUFFEUR | C8: 🔗 IDENTIFIANTS PLATEFORMES | E8: 📞 CONTACT & COORDONNÉES | I8: ⚫ PRODUCTION UBER (€) | K8: 🟢 PRODUCTION BOLT (€) | M8: 💰 TOTAL ENCAISSÉ (€) | N8: ⚙️ ARBITRAGES FLOTTE (€) | R8: 🏦 CASE VIREMENT NET (€) | S8: 💳 IBAN QONTO
A9: N° | B9: Nom Prénom (Chauffeur) | C9: Nom Uber | D9: Nom Bolt | E9: Mail Uber | F9: Mail Bolt | G9: Tél. Uber | H9: Tél. Bolt | I9: Virement Réel Uber (€) | J9: Espèces Uber (€) | K9: Virement Réel Bolt (€) | L9: Espèces Bolt (€) | M9: Total Réel Encaissé (Uber + Bolt) (€) | N9: Rattachement (€) | O9: Charges (€) | P9: Bonus (€) | Q9: Malus (€) | R9: CASE VIREMENT (NET À ENVOYER) (€) | S9: RIB / IBAN (QONTO)
A10: 01 | B10: Abdallah Hamzi | C10: ABDALLAH HAMZI | E10: hamzi.obayda@gmail.com | G10: +33624017099 | I10: 14.08 | J10: =IF(B10="", "", IF(OR(C10="", C10="—"), 0, IFNA(XLOOKUP(C10, DATA_UBER!A:A, DATA_UBER!J:J, 0), 0))) | K10: =IF(B10="", "", IF(OR(D10="", D10="—"), 0, IFNA(XLOOKUP(D10, DATA_BOLT!A:A, DATA_BOLT!Z:Z, 0), 0))) | L10: =IF(B10="", "", IF(OR(D10="", D10="—"), 0, IFNA(XLOOKUP(D10, DATA_BOLT!A:A, DATA_BOLT!G:G, 0), 0))) | M10: 14.08 | N10: 50 | O10: 0 | P10: 0 | Q10: 0 | R10: -35.92
A11: 02 | B11: Abdoul Azize Mohamed Safir | C11: ABDOUL AZIZE MOHAMED SAFIR | D11: Abdoul Azize MOHAMED SAFIR | E11: abazizsafir.pro@gmail.com | F11: abazizsafir.pro@gmail.com | G11: +33761529386 | H11: +33761529386 | I11: 93.96 | J11: =IF(B11="", "", IF(OR(C11="", C11="—"), 0, IFNA(XLOOKUP(C11, DATA_UBER!A:A, DATA_UBER!J:J, 0), 0))) | K11: 133.22 | L11: 361.9 | M11: 227.18 | N11: 50 | O11: 0 | P11: 0 | Q11: 0 | R11: 177.18
A12: 03 | B12: Bechir Ben Smida | C12: Bechir Ben Smida | E12: bsbm67@gmail.com | G12: +33762923919 | I12: 162.02 | J12: =IF(B12="", "", IF(OR(C12="", C12="—"), 0, IFNA(XLOOKUP(C12, DATA_UBER!A:A, DATA_UBER!J:J, 0), 0))) | K12: =IF(B12="", "", IF(OR(D12="", D12="—"), 0, IFNA(XLOOKUP(D12, DATA_BOLT!A:A, DATA_BOLT!Z:Z, 0), 0))) | L12: =IF(B12="", "", IF(OR(D12="", D12="—"), 0, IFNA(XLOOKUP(D12, DATA_BOLT!A:A, DATA_BOLT!G:G, 0), 0))) | M12: 162.02 | N12: 50 | O12: 0 | P12: 0 | Q12: 0 | R12: 112.02
A13: 04 | B13: Fathia Boufalgha | C13: FATHIA BOUFALGHA | E13: titiprestige75@gmail.com | G13: +33759625661 | I13: 159.89 | J13: =IF(B13="", "", IF(OR(C13="", C13="—"), 0, IFNA(XLOOKUP(C13, DATA_UBER!A:A, DATA_UBER!J:J, 0), 0))) | K13: =IF(B13="", "", IF(OR(D13="", D13="—"), 0, IFNA(XLOOKUP(D13, DATA_BOLT!A:A, DATA_BOLT!Z:Z, 0), 0))) | L13: =IF(B13="", "", IF(OR(D13="", D13="—"), 0, IFNA(XLOOKUP(D13, DATA_BOLT!A:A, DATA_BOLT!G:G, 0), 0))) | M13: 159.89 | N13: 50 | O13: 137.5 | P13: 0 | Q13: 0 | R13: -27.61
A14: 05 | B14: Rachid Chinoune | C14: rachid CHINOUNE | D14: Rachid Chinoune | E14: rachidchinoune@yahoo.fr | F14: crtp2023@gmail.com | G14: +33619305126 | H14: +33619305126 | I14: 68.55 | J14: =IF(B14="", "", IF(OR(C14="", C14="—"), 0, IFNA(XLOOKUP(C14, DATA_UBER!A:A, DATA_UBER!J:J, 0), 0))) | K14: 50.92 | L14: =IF(B14="", "", IF(OR(D14="", D14="—"), 0, IFNA(XLOOKUP(D14, DATA_BOLT!A:A, DATA_BOLT!G:G, 0), 0))) | M14: 119.47 | N14: 50 | O14: 0 | P14: 0 | Q14: 0 | R14: 69.47
A15: 06 | B15: Salah Fitouri | C15: Salah Fitouri | E15: Salih071@live.fr | G15: +33627393006 | I15: =IF(B15="", "", IF(OR(C15="", C15="—"), 0, IFNA(XLOOKUP(C15, DATA_UBER!A:A, DATA_UBER!Z:Z, 0), 0))) | J15: =IF(B15="", "", IF(OR(C15="", C15="—"), 0, IFNA(XLOOKUP(C15, DATA_UBER!A:A, DATA_UBER!J:J, 0), 0))) | K15: =IF(B15="", "", IF(OR(D15="", D15="—"), 0, IFNA(XLOOKUP(D15, DATA_BOLT!A:A, DATA_BOLT!Z:Z, 0), 0))) | L15: =IF(B15="", "", IF(OR(D15="", D15="—"), 0, IFNA(XLOOKUP(D15, DATA_BOLT!A:A, DATA_BOLT!G:G, 0), 0))) | M15: =IF(B15="", "", I15 + K15) | N15: =IF(B15="", "", IF(OR(I15<>0, K15<>0, J15<>0, L15<>0), IFNA(XLOOKUP(B15, ANNUAIRE_FLOTTE!B:B, ANNUAIRE_FLOTTE!J:J, 50), 50), 0)) | O15: 0 | P15: 0 | Q15: 0 | R15: =IF(B15="", "", M15 - N15 - O15 - Q15 + P15)
A16: 07 | B16: Bouchaib Belkharras | C16: Bouchaib Belkharras | D16: Bouchaïb Belkharras | E16: belbouch92@gmail.com | F16: bouch.bb@hotmail.com | G16: +33658123002 | H16: +33658123002 | I16: =IF(B16="", "", IF(OR(C16="", C16="—"), 0, IFNA(XLOOKUP(C16, DATA_UBER!A:A, DATA_UBER!Z:Z, 0), 0))) | J16: =IF(B16="", "", IF(OR(C16="", C16="—"), 0, IFNA(XLOOKUP(C16, DATA_UBER!A:A, DATA_UBER!J:J, 0), 0))) | K16: 350.58 | L16: 136.7 | M16: 350.58 | N16: 60 | O16: 0 | P16: 0 | Q16: 0 | R16: 290.58
A17: 08 | B17: Brandon Jean Jimmy Louissaint | C17: BRANDON JEAN-JIMMY LOUISSAINT | D17: Brandon Jean Jimmy Louissaint | E17: louissaintbrandon@hotmail.com | F17: louissaintbrandon@hotmail.com | G17: +33635481157 | H17: +33635481157 | I17: =IF(B17="", "", IF(OR(C17="", C17="—"), 0, IFNA(XLOOKUP(C17, DATA_UBER!A:A, DATA_UBER!Z:Z, 0), 0))) | J17: =IF(B17="", "", IF(OR(C17="", C17="—"), 0, IFNA(XLOOKUP(C17, DATA_UBER!A:A, DATA_UBER!J:J, 0), 0))) | K17: 330.54 | L17: 334.8 | M17: 330.54 | N17: 60 | O17: 0 | P17: 0 | Q17: 0 | R17: 270.54
